Workbook
Name weiblich9: #REF!
Name weiblich7: #REF!
Name n2m: #REF!
Name N1m: #REF!
Name männlich10: #REF!
Name n4w: #REF!
Name N1w: #REF!
Name weiblich11: #REF!
Name n4m: #REF!
Name weiblich12: #REF!
Name n2w: #REF!
Name männlich9: #REF!
Name männlich12: #REF!
Name n3w: #REF!
Name weiblich10: #REF!
Name männlich8: #REF!
Name männlich11: #REF!
Name mannlich7: #REF!
Name n3m: #REF!
Name weiblich8: #REF!

Sheet Eingabe
A1: Klasse | B1: Name | C1: Vorname | D1: Geburtsjahr | E1: M/W | F1: Stufe | G1: Alter | H1: Ausdauer | I1: P. Ausdauer | J1: Sprint | K1: P. Sprint | L1: Sprung | M1: P. Sprung | N1: Wurf | O1: P.Wurf | P1: Datenblatt | Q1: Notenblatt | R1: Gesamt | S1: Urkunde | T1: Note
A2: =IF(ASV_Daten!A21="","",ASV_Daten!A21) -> R5A | B2: =IF(ASV_Daten!B21="","",ASV_Daten!B21) -> Seifried | C2: =IF(ASV_Daten!C21="","",ASV_Daten!C21) -> Oskar | D2: =IF(ASV_Daten!D21="","",ASV_Daten!D21) -> 2015 | E2: =IF(ASV_Daten!E20="","",ASV_Daten!E20) -> M | F2: =MID(A2,2,1) -> 5 | G2: =2026-D2 -> 11 | H2: 0.18402778 | I2: =IF(H2="", 0, IFERROR(XLOOKUP(H2, INDIRECT("'"&P2&"'!A4:A"), INDIRECT("'"&P2&"'!B4:B"), 0, 1), 0)) -> 266 | K2: =IF(J2="", 0, IFERROR(XLOOKUP(J2, INDIRECT("'"&P2&"'!E4:E"), INDIRECT("'"&P2&"'!F4:F"), 0, 1), 0)) -> 0 | L2: 4.93 | M2: =IF(L2="", 0, IFERROR(XLOOKUP(L2, INDIRECT("'"&P2&"'!I4:I"), INDIRECT("'"&P2&"'!J4:J"), 0, -1), 0)) -> 488 | N2: 34.5 | O2: =IF(N2="", 0, IFERROR(XLOOKUP(N2, INDIRECT("'"&P2&"'!M4:M"), INDIRECT("'"&P2&"'!N4:N"), 0, -1), 0)) -> 279 | P2: =IF(OR(F2="6",F2="5"),IF(E2="W","Punkte W 5-6","Punkte M 5-6"),IF(E2="W","Punkte W 7-9","Punkte M 7-9")) -> Punkte M 5-6 | Q2: =IF(E2="W","Noten-Matrix-Mädchen","Noten-Matrix-Jungen") -> Noten-Matrix-Jungen | R2: =SUM(I2, K2, M2, O2) - MIN(I2, K2, M2, O2) -> 1033 | S2: =IF(R2=0, "Keine Teilnahme", IFERROR(IF(R2>=VLOOKUP(G2&LOWER(E2), Formeln!$H$2:$K$30, 4, FALSE), "Ehrenurkunde", IF(R2>=VLOOKUP(G2&LOWER(E2), Formeln!$H$2:$K$30, 3, FALSE), "Siegerurkunde", "Teilnehmerurkunde")), "Keine Urkunde")) -> Ehrenurkunde | T2: =IF(R2=0, "Keine Teilnahme", IFERROR(XLOOKUP(R2, INDEX(INDIRECT("'"&Q2&"'!A:J"), 0, MATCH(G2, INDIRECT("'"&Q2&"'!A1:J1"), 0)), INDIRECT("'"&Q2&"'!A:A"), "Keine Note", -1), "Keine Note")) -> 1
A3: =IF(ASV_Daten!A5="","",ASV_Daten!A5) -> R5A | B3: =IF(ASV_Daten!B5="","",ASV_Daten!B5) -> Gajic | C3: =IF(ASV_Daten!C5="","",ASV_Daten!C5) -> Aleksa | D3: =IF(ASV_Daten!D5="","",ASV_Daten!D5) -> 2014 | E3: =IF(ASV_Daten!E5="","",ASV_Daten!E5) -> M | F3: =MID(A3,2,1) -> 5 | G3: =2026-D3 -> 12 | H3: 0.23333333 | I3: =IF(H3="", 0, IFERROR(XLOOKUP(H3, INDIRECT("'"&P3&"'!A4:A"), INDIRECT("'"&P3&"'!B4:B"), 0, 1), 0)) -> 136 | K3: =IF(J3="", 0, IFERROR(XLOOKUP(J3, INDIRECT("'"&P3&"'!E4:E"), INDIRECT("'"&P3&"'!F4:F"), 0, 1), 0)) -> 0 | L3: 3.21 | M3: =IF(L3="", 0, IFERROR(XLOOKUP(L3, INDIRECT("'"&P3&"'!I4:I"), INDIRECT("'"&P3&"'!J4:J"), 0, -1), 0)) -> 292 | N3: 22.5 | O3: =IF(N3="", 0, IFERROR(XLOOKUP(N3, INDIRECT("'"&P3&"'!M4:M"), INDIRECT("'"&P3&"'!N4:N"), 0, -1), 0)) -> 176 | P3: =IF(OR(F3="6",F3="5"),IF(E3="W","Punkte W 5-6","Punkte M 5-6"),IF(E3="W","Punkte W 7-9","Punkte M 7-9")) -> Punkte M 5-6 | Q3: =IF(E3="W","Noten-Matrix-Mädchen","Noten-Matrix-Jungen") -> Noten-Matrix-Jungen | R3: =SUM(I3, K3, M3, O3) - MIN(I3, K3, M3, O3) -> 604 | S3: =IF(R3=0, "Keine Teilnahme", IFERROR(IF(R3>=VLOOKUP(G3&LOWER(E3), Formeln!$H$2:$K$30, 4, FALSE), "Ehrenurkunde", IF(R3>=VLOOKUP(G3&LOWER(E3), Formeln!$H$2:$K$30, 3, FALSE), "Siegerurkunde", "Teilnehmerurkunde")), "Keine Urkunde")) -> Teilnehmerurkunde | T3: =IF(R3=0, "Keine Teilnahme", IFERROR(XLOOKUP(R3, INDEX(INDIRECT("'"&Q3&"'!A:J"), 0, MATCH(G3, INDIRECT("'"&Q3&"'!A1:J1"), 0)), INDIRECT("'"&Q3&"'!A:A"), "Keine Note", -1), "Keine Note")) -> 3.8
A4: =IF(ASV_Daten!A10="","",ASV_Daten!A10) -> R5A | B4: =IF(ASV_Daten!B10="","",ASV_Daten!B10) -> Keppel | C4: =IF(ASV_Daten!C10="","",ASV_Daten!C10) -> Amelia | D4: =IF(ASV_Daten!D10="","",ASV_Daten!D10) -> 2014 | E4: =IF(ASV_Daten!E10="","",ASV_Daten!E10) -> W | F4: =MID(A4,2,1) -> 5 | G4: =2026-D4 -> 12 | I4: =IF(H4="", 0, IFERROR(XLOOKUP(H4, INDIRECT("'"&P4&"'!A4:A"), INDIRECT("'"&P4&"'!B4:B"), 0, 1), 0)) -> 0 | J4: 9.4 | K4: =IF(J4="", 0, IFERROR(XLOOKUP(J4, INDIRECT("'"&P4&"'!E4:E"), INDIRECT("'"&P4&"'!F4:F"), 0, 1), 0)) -> 233 | L4: 3.01 | M4: =IF(L4="", 0, IFERROR(XLOOKUP(L4, INDIRECT("'"&P4&"'!I4:I"), INDIRECT("'"&P4&"'!J4:J"), 0, -1), 0)) -> 308 | N4: 15 | O4: =IF(N4="", 0, IFERROR(XLOOKUP(N4, INDIRECT("'"&P4&"'!M4:M"), INDIRECT("'"&P4&"'!N4:N"), 0, -1), 0)) -> 211 | P4: =IF(OR(F4="6",F4="5"),IF(E4="W","Punkte W 5-6","Punkte M 5-6"),IF(E4="W","Punkte W 7-9","Punkte M 7-9")) -> Punkte W 5-6 | Q4: =IF(E4="W","Noten-Matrix-Mädchen","Noten-Matrix-Jungen") -> Noten-Matrix-Mädchen | R4: =SUM(I4, K4, M4, O4) - MIN(I4, K4, M4, O4) -> 752 | S4: =IF(R4=0, "Keine Teilnahme", IFERROR(IF(R4>=VLOOKUP(G4&LOWER(E4), Formeln!$H$2:$K$30, 4, FALSE), "Ehrenurkunde", IF(R4>=VLOOKUP(G4&LOWER(E4), Formeln!$H$2:$K$30, 3, FALSE), "Siegerurkunde", "Teilnehmerurkunde")), "Keine Urkunde")) -> Teilnehmerurkunde | T4: =IF(R4=0, "Keine Teilnahme", IFERROR(XLOOKUP(R4, INDEX(INDIRECT("'"&Q4&"'!A:J"), 0, MATCH(G4, INDIRECT("'"&Q4&"'!A1:J1"), 0)), INDIRECT("'"&Q4&"'!A:A"), "Keine Note", -1), "Keine Note")) -> 2.9
A5: =IF(ASV_Daten!A15="","",ASV_Daten!A15) -> R5A | B5: =IF(ASV_Daten!B15="","",ASV_Daten!B15) -> Matos Martins | C5: =IF(ASV_Daten!C15="","",ASV_Daten!C15) -> Beatriz | D5: =IF(ASV_Daten!D15="","",ASV_Daten!D15) -> 2015 | E5: =IF(ASV_Daten!E15="","",ASV_Daten!E15) -> W | F5: =MID(A5,2,1) -> 5 | G5: =2026-D5 -> 11 | I5: =IF(H5="", 0, IFERROR(XLOOKUP(H5, INDIRECT("'"&P5&"'!A4:A"), INDIRECT("'"&P5&"'!B4:B"), 0, 1), 0)) -> 0 | J5: 9.7 | K5: =IF(J5="", 0, IFERROR(XLOOKUP(J5, INDIRECT("'"&P5&"'!E4:E"), INDIRECT("'"&P5&"'!F4:F"), 0, 1), 0)) -> 209 | L5: 2.61 | M5: =IF(L5="", 0, IFERROR(XLOOKUP(L5, INDIRECT("'"&P5&"'!I4:I"), INDIRECT("'"&P5&"'!J4:J"), 0, -1), 0)) -> 250 | N5: 11 | O5: =IF(N5="", 0, IFERROR(XLOOKUP(N5, INDIRECT("'"&P5&"'!M4:M"), INDIRECT("'"&P5&"'!N4:N"), 0, -1), 0)) -> 147 | P5: =IF(OR(F5="6",F5="5"),IF(E5="W","Punkte W 5-6","Punkte M 5-6"),IF(E5="W","Punkte W 7-9","Punkte M 7-9")) -> Punkte W 5-6 | Q5: =IF(E5="W","Noten-Matrix-Mädchen","Noten-Matrix-Jungen") -> Noten-Matrix-Mädchen | R5: =SUM(I5, K5, M5, O5) - MIN(I5, K5, M5, O5) -> 606 | S5: =IF(R5=0, "Keine Teilnahme", IFERROR(IF(R5>=VLOOKUP(G5&LOWER(E5), Formeln!$H$2:$K$30, 4, FALSE), "Ehrenurkunde", IF(R5>=VLOOKUP(G5&LOWER(E5), Formeln!$H$2:$K$30, 3, FALSE), "Siegerurkunde", "Teilnehmerurkunde")), "Keine Urkunde")) -> Teilnehmerurkunde | T5: =IF(R5=0, "Keine Teilnahme", IFERROR(XLOOKUP(R5, INDEX(INDIRECT("'"&Q5&"'!A:J"), 0, MATCH(G5, INDIRECT("'"&Q5&"'!A1:J1"), 0)), INDIRECT("'"&Q5&"'!A:A"), "Keine Note", -1), "Keine Note")) -> 3.4
A6: =IF(ASV_Daten!A19="","",ASV_Daten!A19) -> R5A | B6: =IF(ASV_Daten!B19="","",ASV_Daten!B19) -> Roso | C6: =IF(ASV_Daten!C19="","",ASV_Daten!C19) -> Dejan | D6: =IF(ASV_Daten!D19="","",ASV_Daten!D19) -> 2015 | E6: =IF(ASV_Daten!E19="","",ASV_Daten!E19) -> M | F6: =MID(A6,2,1) -> 5 | G6: =2026-D6 -> 11 | H6: 0.19097222 | I6: =IF(H6="", 0, IFERROR(XLOOKUP(H6, INDIRECT("'"&P6&"'!A4:A"), INDIRECT("'"&P6&"'!B4:B"), 0, 1), 0)) -> 244 | K6: =IF(J6="", 0, IFERROR(XLOOKUP(J6, INDIRECT("'"&P6&"'!E4:E"), INDIRECT("'"&P6&"'!F4:F"), 0, 1), 0)) -> 0 | L6: 3.09 | M6: =IF(L6="", 0, IFERROR(XLOOKUP(L6, INDIRECT("'"&P6&"'!I4:I"), INDIRECT("'"&P6&"'!J4:J"), 0, -1), 0)) -> 277 | N6: 28 | O6: =IF(N6="", 0, IFERROR(XLOOKUP(N6, INDIRECT("'"&P6&"'!M4:M"), INDIRECT("'"&P6&"'!N4:N"), 0, -1), 0)) -> 226 | P6: =IF(OR(F6="6",F6="5"),IF(E6="W","Punkte W 5-6","Punkte M 5-6"),IF(E6="W","Punkte W 7-9","Punkte M 7-9")) -> Punkte M 5-6 | Q6: =IF(E6="W","Noten-Matrix-Mädchen","Noten-Matrix-Jungen") -> Noten-Matrix-Jungen | R6: =SUM(I6, K6, M6, O6) - MIN(I6, K6, M6, O6) -> 747 | S6: =IF(R6=0, "Keine Teilnahme", IFERROR(IF(R6>=VLOOKUP(G6&LOWER(E6), Formeln!$H$2:$K$30, 4, FALSE), "Ehrenurkunde", IF(R6>=VLOOKUP(G6&LOWER(E6), Formeln!$H$2:$K$30, 3, FALSE), "Siegerurkunde", "Teilnehmerurkunde")), "Keine Urkunde")) -> Siegerurkunde | T6: =IF(R6=0, "Keine Teilnahme", IFERROR(XLOOKUP(R6, INDEX(INDIRECT("'"&Q6&"'!A:J"), 0, MATCH(G6, INDIRECT("'"&Q6&"'!A1:J1"), 0)), INDIRECT("'"&Q6&"'!A:A"), "Keine Note", -1), "Keine Note")) -> 2.3
A7: =IF(ASV_Daten!A20="","",ASV_Daten!A20) -> R5A | B7: =IF(ASV_Daten!B20="","",ASV_Daten!B20) -> Schuler | C7: =IF(ASV_Daten!C20="","",ASV_Daten!C20) -> Adrian | D7: =IF(ASV_Daten!D20="","",ASV_Daten!D20) -> 2015 | E7: =IF(ASV_Daten!E22="","",ASV_Daten!E22) -> M | F7: =MID(A7,2,1) -> 5 | G7: =2026-D7 -> 11 | H7: 0.18611111 | I7: =IF(H7="", 0, IFERROR(XLOOKUP(H7, INDIRECT("'"&P7&"'!A4:A"), INDIRECT("'"&P7&"'!B4:B"), 0, 1), 0)) -> 262 | K7: =IF(J7="", 0, IFERROR(XLOOKUP(J7, INDIRECT("'"&P7&"'!E4:E"), INDIRECT("'"&P7&"'!F4:F"), 0, 1), 0)) -> 0 | L7: 3.61 | M7: =IF(L7="", 0, IFERROR(XLOOKUP(L7, INDIRECT("'"&P7&"'!I4:I"), INDIRECT("'"&P7&"'!J4:J"), 0, -1), 0)) -> 342 | N7: 23 | O7: =IF(N7="", 0, IFERROR(XLOOKUP(N7, INDIRECT("'"&P7&"'!M4:M"), INDIRECT("'"&P7&"'!N4:N"), 0, -1), 0)) -> 181 | P7: =IF(OR(F7="6",F7="5"),IF(E7="W","Punkte W 5-6","Punkte M 5-6"),IF(E7="W","Punkte W 7-9","Punkte M 7-9")) -> Punkte M 5-6 | Q7: =IF(E7="W","Noten-Matrix-Mädchen","Noten-Matrix-Jungen") -> Noten-Matrix-Jungen | R7: =SUM(I7, K7, M7, O7) - MIN(I7, K7, M7, O7) -> 785 | S7: =IF(R7=0, "Keine Teilnahme", IFERROR(IF(R7>=VLOOKUP(G7&LOWER(E7), Formeln!$H$2:$K$30, 4, FALSE), "Ehrenurkunde", IF(R7>=VLOOKUP(G7&LOWER(E7), Formeln!$H$2:$K$30, 3, FALSE), "Siegerurkunde", "Teilnehmerurkunde")), "Keine Urkunde")) -> Siegerurkunde | T7: =IF(R7=0, "Keine Teilnahme", IFERROR(XLOOKUP(R7, INDEX(INDIRECT("'"&Q7&"'!A:J"), 0, MATCH(G7, INDIRECT("'"&Q7&"'!A1:J1"), 0)), INDIRECT("'"&Q7&"'!A:A"), "Keine Note", -1), "Keine Note")) -> 2
A8: =IF(ASV_Daten!A25="","",ASV_Daten!A25) -> R5A | B8: =IF(ASV_Daten!B25="","",ASV_Daten!B25) -> Waldvogel | C8: =IF(ASV_Daten!C25="","",ASV_Daten!C25) -> Finn | D8: =IF(ASV_Daten!D25="","",ASV_Daten!D25) -> 2015 | E8: =IF(ASV_Daten!E25="","",ASV_Daten!E25) -> M | F8: =MID(A8,2,1) -> 5 | G8: =2026-D8 -> 11 | I8: =IF(H8="", 0, IFERROR(XLOOKUP(H8, INDIRECT("'"&P8&"'!A4:A"), INDIRECT("'"&P8&"'!B4:B"), 0, 1), 0)) -> 0 | J8: 7.2 | K8: =IF(J8="", 0, IFERROR(XLOOKUP(J8, INDIRECT("'"&P8&"'!E4:E"), INDIRECT("'"&P8&"'!F4:F"), 0, 1), 0)) -> 424 | L8: 2.69 | M8: =IF(L8="", 0, IFERROR(XLOOKUP(L8, INDIRECT("'"&P8&"'!I4:I"), INDIRECT("'"&P8&"'!J4:J"), 0, -1), 0)) -> 223 | N8: 19 | O8: =IF(N8="", 0, IFERROR(XLOOKUP(N8, INDIRECT("'"&P8&"'!M4:M"), INDIRECT("'"&P8&"'!N4:N"), 0, -1), 0)) -> 141 | P8: =IF(OR(F8="6",F8="5"),IF(E8="W","Punkte W 5-6","Punkte M 5-6"),IF(E8="W","Punkte W 7-9","Punkte M 7-9")) -> Punkte M 5-6 | Q8: =IF(E8="W","Noten-Matrix-Mädchen","Noten-Matrix-Jungen") -> Noten-Matrix-Jungen | R8: =SUM(I8, K8, M8, O8) - MIN(I8, K8, M8, O8) -> 788 | S8: =IF(R8=0, "Keine Teilnahme", IFERROR(IF(R8>=VLOOKUP(G8&LOWER(E8), Formeln!$H$2:$K$30, 4, FALSE), "Ehrenurkunde", IF(R8>=VLOOKUP(G8&LOWER(E8), Formeln!$H$2:$K$30, 3, FALSE), "Siegerurkunde", "Teilnehmerurkunde")), "Keine Urkunde")) -> Siegerurkunde | T8: =IF(R8=0, "Keine Teilnahme", IFERROR(XLOOKUP(R8, INDEX(INDIRECT("'"&Q8&"'!A:J"), 0, MATCH(G8, INDIRECT("'"&Q8&"'!A1:J1"), 0)), INDIRECT("'"&Q8&"'!A:A"), "Keine Note", -1), "Keine Note")) -> 2
A9: =IF(ASV_Daten!A12="","",ASV_Daten!A12) -> R5A | B9: =IF(ASV_Daten!B12="","",ASV_Daten!B12) -> Le Roux | C9: =IF(ASV_Daten!C12="","",ASV_Daten!C12) -> Joel | D9: =IF(ASV_Daten!D12="","",ASV_Daten!D12) -> 2015 | E9: =IF(ASV_Daten!E12="","",ASV_Daten!E12) -> M | F9: =MID(A9,2,1) -> 5 | G9: =2026-D9 -> 11 | I9: =IF(H9="", 0, IFERROR(XLOOKUP(H9, INDIRECT("'"&P9&"'!A4:A"), INDIRECT("'"&P9&"'!B4:B"), 0, 1), 0)) -> 0 | J9: 9.5 | K9: =IF(J9="", 0, IFERROR(XLOOKUP(J9, INDIRECT("'"&P9&"'!E4:E"), INDIRECT("'"&P9&"'!F4:F"), 0, 1), 0)) -> 194 | L9: 2.81 | M9: =IF(L9="", 0, IFERROR(XLOOKUP(L9, INDIRECT("'"&P9&"'!I4:I"), INDIRECT("'"&P9&"'!J4:J"), 0, -1), 0)) -> 240 | N9: 23 | O9: =IF(N9="", 0, IFERROR(XLOOKUP(N9, INDIRECT("'"&P9&"'!M4:M"), INDIRECT("'"&P9&"'!N4:N"), 0, -1), 0)) -> 181 | P9: =IF(OR(F9="6",F9="5"),IF(E9="W","Punkte W 5-6","Punkte M 5-6"),IF(E9="W","Punkte W 7-9","Punkte M 7-9")) -> Punkte M 5-6 | Q9: =IF(E9="W","Noten-Matrix-Mädchen","Noten-Matrix-Jungen") -> Noten-Matrix-Jungen | R9: =SUM(I9, K9, M9, O9) - MIN(I9, K9, M9, O9) -> 615 | S9: =IF(R9=0, "Keine Teilnahme", IFERROR(IF(R9>=VLOOKUP(G9&LOWER(E9), Formeln!$H$2:$K$30, 4, FALSE), "Ehrenurkunde", IF(R9>=VLOOKUP(G9&LOWER(E9), Formeln!$H$2:$K$30, 3, FALSE), "Siegerurkunde", "Teilnehmerurkunde")), "Keine Urkunde")) -> Teilnehmerurkunde | T9: =IF(R9=0, "Keine Teilnahme", IFERROR(XLOOKUP(R9, INDEX(INDIRECT("'"&Q9&"'!A:J"), 0, MATCH(G9, INDIRECT("'"&Q9&"'!A1:J1"), 0)), INDIRECT("'"&Q9&"'!A:A"), "Keine Note", -1), "Keine Note")) -> 3.1
A10: =IF(ASV_Daten!A16="","",ASV_Daten!A16) -> R5A | B10: =IF(ASV_Daten!B16="","",ASV_Daten!B16) -> Morina | C10: =IF(ASV_Daten!C16="","",ASV_Daten!C16) -> Lediona | D10: =IF(ASV_Daten!D16="","",ASV_Daten!D16) -> 2015 | E10: =IF(ASV_Daten!E16="","",ASV_Daten!E16) -> W | F10: =MID(A10,2,1) -> 5 | G10: =2026-D10 -> 11 | I10: =IF(H10="", 0, IFERROR(XLOOKUP(H10, INDIRECT("'"&P10&"'!A4:A"), INDIRECT("'"&P10&"'!B4:B"), 0, 1), 0)) -> 0 | J10: 8.6 | K10: =IF(J10="", 0, IFERROR(XLOOKUP(J10, INDIRECT("'"&P10&"'!E4:E"), INDIRECT("'"&P10&"'!F4:F"), 0, 1), 0)) -> 304 | L10: 3.69 | M10: =IF(L10="", 0, IFERROR(XLOOKUP(L10, INDIRECT("'"&P10&"'!I4:I"), INDIRECT("'"&P10&"'!J4:J"), 0, -1), 0)) -> 397 | N10: 19 | O10: =IF(N10="", 0, IFERROR(XLOOKUP(N10, INDIRECT("'"&P10&"'!M4:M"), INDIRECT("'"&P10&"'!N4:N"), 0, -1), 0)) -> 267 | P10: =IF(OR(F10="6",F10="5"),IF(E10="W","Punkte W 5-6","Punkte M 5-6"),IF(E10="W","Punkte W 7-9","Punkte M 7-9")) -> Punkte W 5-6 | Q10: =IF(E10="W","Noten-Matrix-Mädchen","Noten-Matrix-Jungen") -> Noten-Matrix-Mädchen | R10: =SUM(I10, K10, M10, O10) - MIN(I10, K10, M10, O10) -> 968 | S10: =IF(R10=0, "Keine Teilnahme", IFERROR(IF(R10>=VLOOKUP(G10&LOWER(E10), Formeln!$H$2:$K$30, 4, FALSE), "Ehrenurkunde", IF(R10>=VLOOKUP(G10&LOWER(E10), Formeln!$H$2:$K$30, 3, FALSE), "Siegerurkunde", "Teilnehmerurkunde")), "Keine Urkunde")) -> Ehrenurkunde | T10: =IF(R10=0, "Keine Teilnahme", IFERROR(XLOOKUP(R10, INDEX(INDIRECT("'"&Q10&"'!A:J"), 0, MATCH(G10, INDIRECT("'"&Q10&"'!A1:J1"), 0)), INDIRECT("'"&Q10&"'!A:A"), "Keine Note", -1), "Keine Note")) -> 1.2
A11: =IF(ASV_Daten!A4="","",ASV_Daten!A4) -> R5A | B11: =IF(ASV_Daten!B4="","",ASV_Daten!B4) -> Eiche | C11: =IF(ASV_Daten!C4="","",ASV_Daten!C4) -> Lene | D11: =IF(ASV_Daten!D4="","",ASV_Daten!D4) -> 2015 | E11: =IF(ASV_Daten!E4="","",ASV_Daten!E4) -> W | F11: =MID(A11,2,1) -> 5 | G11: =2026-D11 -> 11 | I11: =IF(H11="", 0, IFERROR(XLOOKUP(H11, INDIRECT("'"&P11&"'!A4:A"), INDIRECT("'"&P11&"'!B4:B"), 0, 1), 0)) -> 0 | J11: 9.5 | K11: =IF(J11="", 0, IFERROR(XLOOKUP(J11, INDIRECT("'"&P11&"'!E4:E"), INDIRECT("'"&P11&"'!F4:F"), 0, 1), 0)) -> 225 | L11: 2.89 | M11: =IF(L11="", 0, IFERROR(XLOOKUP(L11, INDIRECT("'"&P11&"'!I4:I"), INDIRECT("'"&P11&"'!J4:J"), 0, -1), 0)) -> 291 | N11: 14 | O11: =IF(N11="", 0, IFERROR(XLOOKUP(N11, INDIRECT("'"&P11&"'!M4:M"), INDIRECT("'"&P11&"'!N4:N"), 0, -1), 0)) -> 196 | P11: =IF(OR(F11="6",F11="5"),IF(E11="W","Punkte W 5-6","Punkte M 5-6"),IF(E11="W","Punkte W 7-9","Punkte M 7-9")) -> Punkte W 5-6 | Q11: =IF(E11="W","Noten-Matrix-Mädchen","Noten-Matrix-Jungen") -> Noten-Matrix-Mädchen | R11: =SUM(I11, K11, M11, O11) - MIN(I11, K11, M11, O11) -> 712 | S11: =IF(R11=0, "Keine Teilnahme", IFERROR(IF(R11>=VLOOKUP(G11&LOWER(E11), Formeln!$H$2:$K$30, 4, FALSE), "Ehrenurkunde", IF(R11>=VLOOKUP(G11&LOWER(E11), Formeln!$H$2:$K$30, 3, FALSE), "Siegerurkunde", "Teilnehmerurkunde")), "Keine Urkunde")) -> Siegerurkunde | T11: =IF(R11=0, "Keine Teilnahme", IFERROR(XLOOKUP(R11, INDEX(INDIRECT("'"&Q11&"'!A:J"), 0, MATCH(G11, INDIRECT("'"&Q11&"'!A1:J1"), 0)), INDIRECT("'"&Q11&"'!A:A"), "Keine Note", -1), "Keine Note")) -> 2.7
A12: =IF(ASV_Daten!A3="","",ASV_Daten!A3) -> R5A | B12: =IF(ASV_Daten!B3="","",ASV_Daten!B3) -> Böttcher | C12: =IF(ASV_Daten!C3="","",ASV_Daten!C3) -> Lian | D12: =IF(ASV_Daten!D3="","",ASV_Daten!D3) -> 2015 | E12: =IF(ASV_Daten!E3="","",ASV_Daten!E3) -> M | F12: =MID(A12,2,1) -> 5 | G12: =2026-D12 -> 11 | H12: 0.20069444 | I12: =IF(H12="", 0, IFERROR(XLOOKUP(H12, INDIRECT("'"&P12&"'!A4:A"), INDIRECT("'"&P12&"'!B4:B"), 0, 1), 0)) -> 213 | K12: =IF(J12="", 0, IFERROR(XLOOKUP(J12, INDIRECT("'"&P12&"'!E4:E"), INDIRECT("'"&P12&"'!F4:F"), 0, 1), 0)) -> 0 | L12: 3.09 | M12: =IF(L12="", 0, IFERROR(XLOOKUP(L12, INDIRECT("'"&P12&"'!I4:I"), INDIRECT("'"&P12&"'!J4:J"), 0, -1), 0)) -> 277 | N12: 23 | O12: =IF(N12="", 0, IFERROR(XLOOKUP(N12, INDIRECT("'"&P12&"'!M4:M"), INDIRECT("'"&P12&"'!N4:N"), 0, -1), 0)) -> 181 | P12: =IF(OR(F12="6",F12="5"),IF(E12="W","Punkte W 5-6","Punkte M 5-6"),IF(E12="W","Punkte W 7-9","Punkte M 7-9")) -> Punkte M 5-6 | Q12: =IF(E12="W","Noten-Matrix-Mädchen","Noten-Matrix-Jungen") -> Noten-Matrix-Jungen | R12: =SUM(I12, K12, M12, O12) - MIN(I12, K12, M12, O12) -> 671 | S12: =IF(R12=0, "Keine Teilnahme", IFERROR(IF(R12>=VLOOKUP(G12&LOWER(E12), Formeln!$H$2:$K$30, 4, FALSE), "Ehrenurkunde", IF(R12>=VLOOKUP(G12&LOWER(E12), Formeln!$H$2:$K$30, 3, FALSE), "Siegerurkunde", "Teilnehmerurkunde")), "Keine Urkunde")) -> Teilnehmerurkunde | T12: =IF(R12=0, "Keine Teilnahme", IFERROR(XLOOKUP(R12, INDEX(INDIRECT("'"&Q12&"'!A:J"), 0, MATCH(G12, INDIRECT("'"&Q12&"'!A1:J1"), 0)), INDIRECT("'"&Q12&"'!A:A"), "Keine Note", -1), "Keine Note")) -> 2.8
A13: =IF(ASV_Daten!A6="","",ASV_Daten!A6) -> R5A | B13: =IF(ASV_Daten!B6="","",ASV_Daten!B6) -> Hajdaraj | C13: =IF(ASV_Daten!C6="","",ASV_Daten!C6) -> Lorik | D13: =IF(ASV_Daten!D6="","",ASV_Daten!D6) -> 2015 | E13: =IF(ASV_Daten!E6="","",ASV_Daten!E6) -> M | F13: =MID(A13,2,1) -> 5 | G13: =2026-D13 -> 11 | H13: 0.1875 | I13: =IF(H13="", 0, IFERROR(XLOOKUP(H13, INDIRECT("'"&P13&"'!A4:A"), INDIRECT("'"&P13&"'!B4:B"), 0, 1), 0)) -> 257 | K13: =IF(J13="", 0, IFERROR(XLOOKUP(J13, INDIRECT("'"&P13&"'!E4:E"), INDIRECT("'"&P13&"'!F4:F"), 0, 1), 0)) -> 0 | L13: 3.29 | M13: =IF(L13="", 0, IFERROR(XLOOKUP(L13, INDIRECT("'"&P13&"'!I4:I"), INDIRECT("'"&P13&"'!J4:J"), 0, -1), 0)) -> 302 | N13: 24.5 | O13: =IF(N13="", 0, IFERROR(XLOOKUP(N13, INDIRECT("'"&P13&"'!M4:M"), INDIRECT("'"&P13&"'!N4:N"), 0, -1), 0)) -> 195 | P13: =IF(OR(F13="6",F13="5"),IF(E13="W","Punkte W 5-6","Punkte M 5-6"),IF(E13="W","Punkte W 7-9","Punkte M 7-9")) -> Punkte M 5-6 | Q13: =IF(E13="W","Noten-Matrix-Mädchen","Noten-Matrix-Jungen") -> Noten-Matrix-Jungen | R13: =SUM(I13, K13, M13, O13) - MIN(I13, K13, M13, O13) -> 754 | S13: =IF(R13=0, "Keine Teilnahme", IFERROR(IF(R13>=VLOOKUP(G13&LOWER(E13), Formeln!$H$2:$K$30, 4, FALSE), "Ehrenurkunde", IF(R13>=VLOOKUP(G13&LOWER(E13), Formeln!$H$2:$K$30, 3, FALSE), "Siegerurkunde", "Teilnehmerurkunde")), "Keine Urkunde")) -> Siegerurkunde | T13: =IF(R13=0, "Keine Teilnahme", IFERROR(XLOOKUP(R13, INDEX(INDIRECT("'"&Q13&"'!A:J"), 0, MATCH(G13, INDIRECT("'"&Q13&"'!A1:J1"), 0)), INDIRECT("'"&Q13&"'!A:A"), "Keine Note", -1), "Keine Note")) -> 2.2
A14: =IF(ASV_Daten!A23="","",ASV_Daten!A23) -> R5A | B14: =IF(ASV_Daten!B23="","",ASV_Daten!B23) -> Singh | C14: =IF(ASV_Daten!C23="","",ASV_Daten!C23) -> Louis | D14: =IF(ASV_Daten!D23="","",ASV_Daten!D23) -> 2014 | E14: =IF(ASV_Daten!E23="","",ASV_Daten!E23) -> M | F14: =MID(A14,2,1) -> 5 | G14: =2026-D14 -> 12 | I14: =IF(H14="", 0, IFERROR(XLOOKUP(H14, INDIRECT("'"&P14&"'!A4:A"), INDIRECT("'"&P14&"'!B4:B"), 0, 1), 0)) -> 0 | K14: =IF(J14="", 0, IFERROR(XLOOKUP(J14, INDIRECT("'"&P14&"'!E4:E"), INDIRECT("'"&P14&"'!F4:F"), 0, 1), 0)) -> 0 | M14: =IF(L14="", 0, IFERROR(XLOOKUP(L14, INDIRECT("'"&P14&"'!I4:I"), INDIRECT("'"&P14&"'!J4:J"), 0, -1), 0)) -> 0 | O14: =IF(N14="", 0, IFERROR(XLOOKUP(N14, INDIRECT("'"&P14&"'!M4:M"), INDIRECT("'"&P14&"'!N4:N"), 0, -1), 0)) -> 0 | P14: =IF(OR(F14="6",F14="5"),IF(E14="W","Punkte W 5-6","Punkte M 5-6"),IF(E14="W","Punkte W 7-9","Punkte M 7-9")) -> Punkte M 5-6 | Q14: =IF(E14="W","Noten-Matrix-Mädchen","Noten-Matrix-Jungen") -> Noten-Matrix-Jungen | R14: =SUM(I14, K14, M14, O14) - MIN(I14, K14, M14, O14) -> 0 | S14: =IF(R14=0, "Keine Teilnahme", IFERROR(IF(R14>=VLOOKUP(G14&LOWER(E14), Formeln!$H$2:$K$30, 4, FALSE), "Ehrenurkunde", IF(R14>=VLOOKUP(G14&LOWER(E14), Formeln!$H$2:$K$30, 3, FALSE), "Siegerurkunde", "Teilnehmerurkunde")), "Keine Urkunde")) -> Keine Teilnahme | T14: =IF(R14=0, "Keine Teilnahme", IFERROR(XLOOKUP(R14, INDEX(INDIRECT("'"&Q14&"'!A:J"), 0, MATCH(G14, INDIRECT("'"&Q14&"'!A1:J1"), 0)), INDIRECT("'"&Q14&"'!A:A"), "Keine Note", -1), "Keine Note")) -> Keine Teilnahme
A15: =IF(ASV_Daten!A8="","",ASV_Daten!A8) -> R5A | B15: =IF(ASV_Daten!B8="","",ASV_Daten!B8) -> Kaltenbach | C15: =IF(ASV_Daten!C8="","",ASV_Daten!C8) -> Lucia | D15: =IF(ASV_Daten!D8="","",ASV_Daten!D8) -> 2015 | E15: =IF(ASV_Daten!E8="","",ASV_Daten!E8) -> W | F15: =MID(A15,2,1) -> 5 | G15: =2026-D15 -> 11 | I15: =IF(H15="", 0, IFERROR(XLOOKUP(H15, INDIRECT("'"&P15&"'!A4:A"), INDIRECT("'"&P15&"'!B4:B"), 0, 1), 0)) -> 0 | J15: 10.2 | K15: =IF(J15="", 0, IFERROR(XLOOKUP(J15, INDIRECT("'"&P15&"'!E4:E"), INDIRECT("'"&P15&"'!F4:F"), 0, 1), 0)) -> 172 | L15: 2.81 | M15: =IF(L15="", 0, IFERROR(XLOOKUP(L15, INDIRECT("'"&P15&"'!I4:I"), INDIRECT("'"&P15&"'!J4:J"), 0, -1), 0)) -> 280 | N15: 18 | O15: =IF(N15="", 0, IFERROR(XLOOKUP(N15, INDIRECT("'"&P15&"'!M4:M"), INDIRECT("'"&P15&"'!N4:N"), 0, -1), 0)) -> 253 | P15: =IF(OR(F15="6",F15="5"),IF(E15="W","Punkte W 5-6","Punkte M 5-6"),IF(E15="W","Punkte W 7-9","Punkte M 7-9")) -> Punkte W 5-6 | Q15: =IF(E15="W","Noten-Matrix-Mädchen","Noten-Matrix-Jungen") -> Noten-Matrix-Mädchen | R15: =SUM(I15, K15, M15, O15) - MIN(I15, K15, M15, O15) -> 705 | S15: =IF(R15=0, "Keine Teilnahme", IFERROR(IF(R15>=VLOOKUP(G15&LOWER(E15), Formeln!$H$2:$K$30, 4, FALSE), "Ehrenurkunde", IF(R15>=VLOOKUP(G15&LOWER(E15), Formeln!$H$2:$K$30, 3, FALSE), "Siegerurkunde", "Teilnehmerurkunde")), "Keine Urkunde")) -> Siegerurkunde | T15: =IF(R15=0, "Keine Teilnahme", IFERROR(XLOOKUP(R15, INDEX(INDIRECT("'"&Q15&"'!A:J"), 0, MATCH(G15, INDIRECT("'"&Q15&"'!A1:J1"), 0)), INDIRECT("'"&Q15&"'!A:A"), "Keine Note", -1), "Keine Note")) -> 2.7
A16: =IF(ASV_Daten!A7="","",ASV_Daten!A7) -> R5A | B16: =IF(ASV_Daten!B7="","",ASV_Daten!B7) -> Herrman | C16: =IF(ASV_Daten!C7="","",ASV_Daten!C7) -> Marlon | D16: =IF(ASV_Daten!D7="","",ASV_Daten!D7) -> 2014 | E16: =IF(ASV_Daten!E7="","",ASV_Daten!E7) -> M | F16: =MID(A16,2,1) -> 5 | G16: =2026-D16 -> 12 | H16: 0.18888889 | I16: =IF(H16="", 0, IFERROR(XLOOKUP(H16, INDIRECT("'"&P16&"'!A4:A"), INDIRECT("'"&P16&"'!B4:B"), 0, 1), 0)) -> 253 | K16: =IF(J16="", 0, IFERROR(XLOOKUP(J16, INDIRECT("'"&P16&"'!E4:E"), INDIRECT("'"&P16&"'!F4:F"), 0, 1), 0)) -> 0 | L16: 3.21 | M16: =IF(L16="", 0, IFERROR(XLOOKUP(L16, INDIRECT("'"&P16&"'!I4:I"), INDIRECT("'"&P16&"'!J4:J"), 0, -1), 0)) -> 292 | N16: 26 | O16: =IF(N16="", 0, IFERROR(XLOOKUP(N16, INDIRECT("'"&P16&"'!M4:M"), INDIRECT("'"&P16&"'!N4:N"), 0, -1), 0)) -> 209 | P16: =IF(OR(F16="6",F16="5"),IF(E16="W","Punkte W 5-6","Punkte M 5-6"),IF(E16="W","Punkte W 7-9","Punkte M 7-9")) -> Punkte M 5-6 | Q16: =IF(E16="W","Noten-Matrix-Mädchen","Noten-Matrix-Jungen") -> Noten-Matrix-Jungen | R16: =SUM(I16, K16, M16, O16) - MIN(I16, K16, M16, O16) -> 754 | S16: =IF(R16=0, "Keine Teilnahme", IFERROR(IF(R16>=VLOOKUP(G16&LOWER(E16), Formeln!$H$2:$K$30, 4, FALSE), "Ehrenurkunde", IF(R16>=VLOOKUP(G16&LOWER(E16), Formeln!$H$2:$K$30, 3, FALSE), "Siegerurkunde", "Teilnehmerurkunde")), "Keine Urkunde")) -> Siegerurkunde | T16: =IF(R16=0, "Keine Teilnahme", IFERROR(XLOOKUP(R16, INDEX(INDIRECT("'"&Q16&"'!A:J"), 0, MATCH(G16, INDIRECT("'"&Q16&"'!A1:J1"), 0)), INDIRECT("'"&Q16&"'!A:A"), "Keine Note", -1), "Keine Note")) -> 2.7
A17: =IF(ASV_Daten!A17="","",ASV_Daten!A17) -> R5A | B17: =IF(ASV_Daten!B17="","",ASV_Daten!B17) -> Pieler | C17: =IF(ASV_Daten!C17="","",ASV_Daten!C17) -> Max | D17: =IF(ASV_Daten!D17="","",ASV_Daten!D17) -> 2015 | E17: =IF(ASV_Daten!E17="","",ASV_Daten!E17) -> M | F17: =MID(A17,2,1) -> 5 | G17: =2026-D17 -> 11 | H17: 0.17916667 | I17: =IF(H17="", 0, IFERROR(XLOOKUP(H17, INDIRECT("'"&P17&"'!A4:A"), INDIRECT("'"&P17&"'!B4:B"), 0, 1), 0)) -> 286 | K17: =IF(J17="", 0, IFERROR(XLOOKUP(J17, INDIRECT("'"&P17&"'!E4:E"), INDIRECT("'"&P17&"'!F4:F"), 0, 1), 0)) -> 0 | L17: 3.81 | M17: =IF(L17="", 0, IFERROR(XLOOKUP(L17, INDIRECT("'"&P17&"'!I4:I"), INDIRECT("'"&P17&"'!J4:J"), 0, -1), 0)) -> 366 | N17: 40 | O17: =IF(N17="", 0, IFERROR(XLOOKUP(N17, INDIRECT("'"&P17&"'!M4:M"), INDIRECT("'"&P17&"'!N4:N"), 0, -1), 0)) -> 320 | P17: =IF(OR(F17="6",F17="5"),IF(E17="W","Punkte W 5-6","Punkte M 5-6"),IF(E17="W","Punkte W 7-9","Punkte M 7-9")) -> Punkte M 5-6 | Q17: =IF(E17="W","Noten-Matrix-Mädchen","Noten-Matrix-Jungen") -> Noten-Matrix-Jungen | R17: =SUM(I17, K17, M17, O17) - MIN(I17, K17, M17, O17) -> 972 | S17: =IF(R17=0, "Keine Teilnahme", IFERROR(IF(R17>=VLOOKUP(G17&LOWER(E17), Formeln!$H$2:$K$30, 4, FALSE), "Ehrenurkunde", IF(R17>=VLOOKUP(G17&LOWER(E17), Formeln!$H$2:$K$30, 3, FALSE), "Siegerurkunde", "Teilnehmerurkunde")), "Keine Urkunde")) -> Ehrenurkunde | T17: =IF(R17=0, "Keine Teilnahme", IFERROR(XLOOKUP(R17, INDEX(INDIRECT("'"&Q17&"'!A:J"), 0, MATCH(G17, INDIRECT("'"&Q17&"'!A1:J1"), 0)), INDIRECT("'"&Q17&"'!A:A"), "Keine Note", -1), "Keine Note")) -> 1.1
A18: =IF(ASV_Daten!A13="","",ASV_Daten!A13) -> R5A | B18: =IF(ASV_Daten!B13="","",ASV_Daten!B13) -> Lickert | C18: =IF(ASV_Daten!C13="","",ASV_Daten!C13) -> Mia | D18: =IF(ASV_Daten!D13="","",ASV_Daten!D13) -> 2014 | E18: =IF(ASV_Daten!E13="","",ASV_Daten!E13) -> W | F18: =MID(A18,2,1) -> 5 | G18: =2026-D18 -> 12 | I18: =IF(H18="", 0, IFERROR(XLOOKUP(H18, INDIRECT("'"&P18&"'!A4:A"), INDIRECT("'"&P18&"'!B4:B"), 0, 1), 0)) -> 0 | J18: 8.5 | K18: =IF(J18="", 0, IFERROR(XLOOKUP(J18, INDIRECT("'"&P18&"'!E4:E"), INDIRECT("'"&P18&"'!F4:F"), 0, 1), 0)) -> 314 | L18: 3.49 | M18: =IF(L18="", 0, IFERROR(XLOOKUP(L18, INDIRECT("'"&P18&"'!I4:I"), INDIRECT("'"&P18&"'!J4:J"), 0, -1), 0)) -> 372 | N18: 19 | O18: =IF(N18="", 0, IFERROR(XLOOKUP(N18, INDIRECT("'"&P18&"'!M4:M"), INDIRECT("'"&P18&"'!N4:N"), 0, -1), 0)) -> 267 | P18: =IF(OR(F18="6",F18="5"),IF(E18="W","Punkte W 5-6","Punkte M 5-6"),IF(E18="W","Punkte W 7-9","Punkte M 7-9")) -> Punkte W 5-6 | Q18: =IF(E18="W","Noten-Matrix-Mädchen","Noten-Matrix-Jungen") -> Noten-Matrix-Mädchen | R18: =SUM(I18, K18, M18, O18) - MIN(I18, K18, M18, O18) -> 953 | S18: =IF(R18=0, "Keine Teilnahme", IFERROR(IF(R18>=VLOOKUP(G18&LOWER(E18), Formeln!$H$2:$K$30, 4, FALSE), "Ehrenurkunde", IF(R18>=VLOOKUP(G18&LOWER(E18), Formeln!$H$2:$K$30, 3, FALSE), "Siegerurkunde", "Teilnehmerurkunde")), "Keine Urkunde")) -> Siegerurkunde | T18: =IF(R18=0, "Keine Teilnahme", IFERROR(XLOOKUP(R18, INDEX(INDIRECT("'"&Q18&"'!A:J"), 0, MATCH(G18, INDIRECT("'"&Q18&"'!A1:J1"), 0)), INDIRECT("'"&Q18&"'!A:A"), "Keine Note", -1), "Keine Note")) -> 1.7
A19: =IF(ASV_Daten!A26="","",ASV_Daten!A26) -> R5A | B19: =IF(ASV_Daten!B26="","",ASV_Daten!B26) -> Ziuzina | C19: =IF(ASV_Daten!C26="","",ASV_Daten!C26) -> Milana | D19: =IF(ASV_Daten!D26="","",ASV_Daten!D26) -> 2014 | E19: =IF(ASV_Daten!E26="","",ASV_Daten!E26) -> W | F19: =MID(A19,2,1) -> 5 | G19: =2026-D19 -> 12 | I19: =IF(H19="", 0, IFERROR(XLOOKUP(H19, INDIRECT("'"&P19&"'!A4:A"), INDIRECT("'"&P19&"'!B4:B"), 0, 1), 0)) -> 0 | J19: 9.4 | K19: =IF(J19="", 0, IFERROR(XLOOKUP(J19, INDIRECT("'"&P19&"'!E4:E"), INDIRECT("'"&P19&"'!F4:F"), 0, 1), 0)) -> 233 | L19: 3.09 | M19: =IF(L19="", 0, IFERROR(XLOOKUP(L19, INDIRECT("'"&P19&"'!I4:I"), INDIRECT("'"&P19&"'!J4:J"), 0, -1), 0)) -> 319 | N19: 10 | O19: =IF(N19="", 0, IFERROR(XLOOKUP(N19, INDIRECT("'"&P19&"'!M4:M"), INDIRECT("'"&P19&"'!N4:N"), 0, -1), 0)) -> 130 | P19: =IF(OR(F19="6",F19="5"),IF(E19="W","Punkte W 5-6","Punkte M 5-6"),IF(E19="W","Punkte W 7-9","Punkte M 7-9")) -> Punkte W 5-6 | Q19: =IF(E19="W","Noten-Matrix-Mädchen","Noten-Matrix-Jungen") -> Noten-Matrix-Mädchen | R19: =SUM(I19, K19, M19, O19) - MIN(I19, K19, M19, O19) -> 682 | S19: =IF(R19=0, "Keine Teilnahme", IFERROR(IF(R19>=VLOOKUP(G19&LOWER(E19), Formeln!$H$2:$K$30, 4, FALSE), "Ehrenurkunde", IF(R19>=VLOOKUP(G19&LOWER(E19), Formeln!$H$2:$K$30, 3, FALSE), "Siegerurkunde", "Teilnehmerurkunde")), "Keine Urkunde")) -> Teilnehmerurkunde | T19: =IF(R19=0, "Keine Teilnahme", IFERROR(XLOOKUP(R19, INDEX(INDIRECT("'"&Q19&"'!A:J"), 0, MATCH(G19, INDIRECT("'"&Q19&"'!A1:J1"), 0)), INDIRECT("'"&Q19&"'!A:A"), "Keine Note", -1), "Keine Note")) -> 3.4
A20: =IF(ASV_Daten!A11="","",ASV_Daten!A11) -> R5A | B20: =IF(ASV_Daten!B11="","",ASV_Daten!B11) -> Kramer | C20: =IF(ASV_Daten!C11="","",ASV_Daten!C11) -> Mira | D20: =IF(ASV_Daten!D11="","",ASV_Daten!D11) -> 2015 | E20: =IF(ASV_Daten!E11="","",ASV_Daten!E11) -> W | F20: =MID(A20,2,1) -> 5 | G20: =2026-D20 -> 11 | I20: =IF(H20="", 0, IFERROR(XLOOKUP(H20, INDIRECT("'"&P20&"'!A4:A"), INDIRECT("'"&P20&"'!B4:B"), 0, 1), 0)) -> 0 | J20: 10.8 | K20: =IF(J20="", 0, IFERROR(XLOOKUP(J20, INDIRECT("'"&P20&"'!E4:E"), INDIRECT("'"&P20&"'!F4:F"), 0, 1), 0)) -> 133 | L20: 2.61 | M20: =IF(L20="", 0, IFERROR(XLOOKUP(L20, INDIRECT("'"&P20&"'!I4:I"), INDIRECT("'"&P20&"'!J4:J"), 0, -1), 0)) -> 250 | N20: 15.5 | O20: =IF(N20="", 0, IFERROR(XLOOKUP(N20, INDIRECT("'"&P20&"'!M4:M"), INDIRECT("'"&P20&"'!N4:N"), 0, -1), 0)) -> 218 | P20: =IF(OR(F20="6",F20="5"),IF(E20="W","Punkte W 5-6","Punkte M 5-6"),IF(E20="W","Punkte W 7-9","Punkte M 7-9")) -> Punkte W 5-6 | Q20: =IF(E20="W","Noten-Matrix-Mädchen","Noten-Matrix-Jungen") -> Noten-Matrix-Mädchen | R20: =SUM(I20, K20, M20, O20) - MIN(I20, K20, M20, O20) -> 601 | S20: =IF(R20=0, "Keine Teilnahme", IFERROR(IF(R20>=VLOOKUP(G20&LOWER(E20), Formeln!$H$2:$K$30, 4, FALSE), "Ehrenurkunde", IF(R20>=VLOOKUP(G20&LOWER(E20), Formeln!$H$2:$K$30, 3, FALSE), "Siegerurkunde", "Teilnehmerurkunde")), "Keine Urkunde")) -> Teilnehmerurkunde | T20: =IF(R20=0, "Keine Teilnahme", IFERROR(XLOOKUP(R20, INDEX(INDIRECT("'"&Q20&"'!A:J"), 0, MATCH(G20, INDIRECT("'"&Q20&"'!A1:J1"), 0)), INDIRECT("'"&Q20&"'!A:A"), "Keine Note", -1), "Keine Note")) -> 3.4
A21: =IF(ASV_Daten!A14="","",ASV_Daten!A14) -> R5A | B21: =IF(ASV_Daten!B14="","",ASV_Daten!B14) -> Magidi | C21: =IF(ASV_Daten!C14="","",ASV_Daten!C14) -> Mobina | D21: =IF(ASV_Daten!D14="","",ASV_Daten!D14) -> 2015 | E21: =IF(ASV_Daten!E14="","",ASV_Daten!E14) -> W | F21: =MID(A21,2,1) -> 5 | G21: =2026-D21 -> 11 | I21: =IF(H21="", 0, IFERROR(XLOOKUP(H21, INDIRECT("'"&P21&"'!A4:A"), INDIRECT("'"&P21&"'!B4:B"), 0, 1), 0)) -> 0 | J21: 10.3 | K21: =IF(J21="", 0, IFERROR(XLOOKUP(J21, INDIRECT("'"&P21&"'!E4:E"), INDIRECT("'"&P21&"'!F4:F"), 0, 1), 0)) -> 166 | L21: 2.69 | M21: =IF(L21="", 0, IFERROR(XLOOKUP(L21, INDIRECT("'"&P21&"'!I4:I"), INDIRECT("'"&P21&"'!J4:J"), 0, -1), 0)) -> 262 | N21: 17.5 | O21: =IF(N21="", 0, IFERROR(XLOOKUP(N21, INDIRECT("'"&P21&"'!M4:M"), INDIRECT("'"&P21&"'!N4:N"), 0, -1), 0)) -> 247 | P21: =IF(OR(F21="6",F21="5"),IF(E21="W","Punkte W 5-6","Punkte M 5-6"),IF(E21="W","Punkte W 7-9","Punkte M 7-9")) -> Punkte W 5-6 | Q21: =IF(E21="W","Noten-Matrix-Mädchen","Noten-Matrix-Jungen") -> Noten-Matrix-Mädchen | R21: =SUM(I21, K21, M21, O21) - MIN(I21, K21, M21, O21) -> 675 | S21: =IF(R21=0, "Keine Teilnahme", IFERROR(IF(R21>=VLOOKUP(G21&LOWER(E21), Formeln!$H$2:$K$30, 4, FALSE), "Ehrenurkunde", IF(R21>=VLOOKUP(G21&LOWER(E21), Formeln!$H$2:$K$30, 3, FALSE), "Siegerurkunde", "Teilnehmerurkunde")), "Keine Urkunde")) -> Teilnehmerurkunde | T21: =IF(R21=0, "Keine Teilnahme", IFERROR(XLOOKUP(R21, INDEX(INDIRECT("'"&Q21&"'!A:J"), 0, MATCH(G21, INDIRECT("'"&Q21&"'!A1:J1"), 0)), INDIRECT("'"&Q21&"'!A:A"), "Keine Note", -1), "Keine Note")) -> 2.9
A22: =IF(ASV_Daten!A9="","",ASV_Daten!A9) -> R5A | B22: =IF(ASV_Daten!B9="","",ASV_Daten!B9) -> Kaltschmidt | C22: =IF(ASV_Daten!C9="","",ASV_Daten!C9) -> Nelly | D22: =IF(ASV_Daten!D9="","",ASV_Daten!D9) -> 2014 | E22: =IF(ASV_Daten!E9="","",ASV_Daten!E9) -> W | F22: =MID(A22,2,1) -> 5 | G22: =2026-D22 -> 12 | H22: 0.15208333 | I22: =IF(H22="", 0, IFERROR(XLOOKUP(H22, INDIRECT("'"&P22&"'!A4:A"), INDIRECT("'"&P22&"'!B4:B"), 0, 1), 0)) -> 249 | K22: =IF(J22="", 0, IFERROR(XLOOKUP(J22, INDIRECT("'"&P22&"'!E4:E"), INDIRECT("'"&P22&"'!F4:F"), 0, 1), 0)) -> 0 | M22: =IF(L22="", 0, IFERROR(XLOOKUP(L22, INDIRECT("'"&P22&"'!I4:I"), INDIRECT("'"&P22&"'!J4:J"), 0, -1), 0)) -> 0 | N22: 18 | O22: =IF(N22="", 0, IFERROR(XLOOKUP(N22, INDIRECT("'"&P22&"'!M4:M"), INDIRECT("'"&P22&"'!N4:N"), 0, -1), 0)) -> 253 | P22: =IF(OR(F22="6",F22="5"),IF(E22="W","Punkte W 5-6","Punkte M 5-6"),IF(E22="W","Punkte W 7-9","Punkte M 7-9")) -> Punkte W 5-6 | Q22: =IF(E22="W","Noten-Matrix-Mädchen","Noten-Matrix-Jungen") -> Noten-Matrix-Mädchen | R22: =SUM(I22, K22, M22, O22) - MIN(I22, K22, M22, O22) -> 502 | S22: =IF(R22=0, "Keine Teilnahme", IFERROR(IF(R22>=VLOOKUP(G22&LOWER(E22), Formeln!$H$2:$K$30, 4, FALSE), "Ehrenurkunde", IF(R22>=VLOOKUP(G22&LOWER(E22), Formeln!$H$2:$K$30, 3, FALSE), "Siegerurkunde", "Teilnehmerurkunde")), "Keine Urkunde")) -> Teilnehmerurkunde | T22: =IF(R22=0, "Keine Teilnahme", IFERROR(XLOOKUP(R22, INDEX(INDIRECT("'"&Q22&"'!A:J"), 0, MATCH(G22, INDIRECT("'"&Q22&"'!A1:J1"), 0)), INDIRECT("'"&Q22&"'!A:A"), "Keine Note", -1), "Keine Note")) -> NOTE
A23: =IF(ASV_Daten!A18="","",ASV_Daten!A18) -> R5A | B23: =IF(ASV_Daten!B18="","",ASV_Daten!B18) -> Rogg | C23: =IF(ASV_Daten!C18="","",ASV_Daten!C18) -> Nico | D23: =IF(ASV_Daten!D18="","",ASV_Daten!D18) -> 2014 | E23: =IF(ASV_Daten!E18="","",ASV_Daten!E18) -> M | F23: =MID(A23,2,1) -> 5 | G23: =2026-D23 -> 12 | H23: 0.20138889 | I23: =IF(H23="", 0, IFERROR(XLOOKUP(H23, INDIRECT("'"&P23&"'!A4:A"), INDIRECT("'"&P23&"'!B4:B"), 0, 1), 0)) -> 213 | K23: =IF(J23="", 0, IFERROR(XLOOKUP(J23, INDIRECT("'"&P23&"'!E4:E"), INDIRECT("'"&P23&"'!F4:F"), 0, 1), 0)) -> 0 | L23: 3.09 | M23: =IF(L23="", 0, IFERROR(XLOOKUP(L23, INDIRECT("'"&P23&"'!I4:I"), INDIRECT("'"&P23&"'!J4:J"), 0, -1), 0)) -> 277 | N23: 25 | O23: =IF(N23="", 0, IFERROR(XLOOKUP(N23, INDIRECT("'"&P23&"'!M4:M"), INDIRECT("'"&P23&"'!N4:N"), 0, -1), 0)) -> 200 | P23: =IF(OR(F23="6",F23="5"),IF(E23="W","Punkte W 5-6","Punkte M 5-6"),IF(E23="W","Punkte W 7-9","Punkte M 7-9")) -> Punkte M 5-6 | Q23: =IF(E23="W","Noten-Matrix-Mädchen","Noten-Matrix-Jungen") -> Noten-Matrix-Jungen | R23: =SUM(I23, K23, M23, O23) - MIN(I23, K23, M23, O23) -> 690 | S23: =IF(R23=0, "Keine Teilnahme", IFERROR(IF(R23>=VLOOKUP(G23&LOWER(E23), Formeln!$H$2:$K$30, 4, FALSE), "Ehrenurkunde", IF(R23>=VLOOKUP(G23&LOWER(E23), Formeln!$H$2:$K$30, 3, FALSE), "Siegerurkunde", "Teilnehmerurkunde")), "Keine Urkunde")) -> Teilnehmerurkunde | T23: =IF(R23=0, "Keine Teilnahme", IFERROR(XLOOKUP(R23, INDEX(INDIRECT("'"&Q23&"'!A:J"), 0, MATCH(G23, INDIRECT("'"&Q23&"'!A1:J1"), 0)), INDIRECT("'"&Q23&"'!A:A"), "Keine Note", -1), "Keine Note")) -> 3.1
A24: =IF(ASV_Daten!A22="","",ASV_Daten!A22) -> R5A | B24: =IF(ASV_Daten!B22="","",ASV_Daten!B22) -> Shahini | C24: =IF(ASV_Daten!C22="","",ASV_Daten!C22) -> Dion | D24: =IF(ASV_Daten!D22="","",ASV_Daten!D22) -> 2014 | E24: =IF(ASV_Daten!E21="","",ASV_Daten!E21) -> M | F24: =MID(A24,2,1) -> 5 | G24: =2026-D24 -> 12 | H24: 0.1875 | I24: =IF(H24="", 0, IFERROR(XLOOKUP(H24, INDIRECT("'"&P24&"'!A4:A"), INDIRECT("'"&P24&"'!B4:B"), 0, 1), 0)) -> 257 | K24: =IF(J24="", 0, IFERROR(XLOOKUP(J24, INDIRECT("'"&P24&"'!E4:E"), INDIRECT("'"&P24&"'!F4:F"), 0, 1), 0)) -> 0 | M24: =IF(L24="", 0, IFERROR(XLOOKUP(L24, INDIRECT("'"&P24&"'!I4:I"), INDIRECT("'"&P24&"'!J4:J"), 0, -1), 0)) -> 0 | O24: =IF(N24="", 0, IFERROR(XLOOKUP(N24, INDIRECT("'"&P24&"'!M4:M"), INDIRECT("'"&P24&"'!N4:N"), 0, -1), 0)) -> 0 | P24: =IF(OR(F24="6",F24="5"),IF(E24="W","Punkte W 5-6","Punkte M 5-6"),IF(E24="W","Punkte W 7-9","Punkte M 7-9")) -> Punkte M 5-6 | Q24: =IF(E24="W","Noten-Matrix-Mädchen","Noten-Matrix-Jungen") -> Noten-Matrix-Jungen | R24: =SUM(I24, K24, M24, O24) - MIN(I24, K24, M24, O24) -> 257 | S24: =IF(R24=0, "Keine Teilnahme", IFERROR(IF(R24>=VLOOKUP(G24&LOWER(E24), Formeln!$H$2:$K$30, 4, FALSE), "Ehrenurkunde", IF(R24>=VLOOKUP(G24&LOWER(E24), Formeln!$H$2:$K$30, 3, FALSE), "Siegerurkunde", "Teilnehmerurkunde")), "Keine Urkunde")) -> Teilnehmerurkunde | T24: =IF(R24=0, "Keine Teilnahme", IFERROR(XLOOKUP(R24, INDEX(INDIRECT("'"&Q24&"'!A:J"), 0, MATCH(G24, INDIRECT("'"&Q24&"'!A1:J1"), 0)), INDIRECT("'"&Q24&"'!A:A"), "Keine Note", -1), "Keine Note")) -> NOTE
A25: =IF(ASV_Daten!A24="","",ASV_Daten!A24) -> R5A | B25: =IF(ASV_Daten!B24="","",ASV_Daten!B24) -> Uhlmann | C25: =IF(ASV_Daten!C24="","",ASV_Daten!C24) -> Paul | D25: =IF(ASV_Daten!D24="","",ASV_Daten!D24) -> 2014 | E25: =IF(ASV_Daten!E24="","",ASV_Daten!E24) -> M | F25: =MID(A25,2,1) -> 5 | G25: =2026-D25 -> 12 | I25: =IF(H25="", 0, IFERROR(XLOOKUP(H25, INDIRECT("'"&P25&"'!A4:A"), INDIRECT("'"&P25&"'!B4:B"), 0, 1), 0)) -> 0 | J25: 9.4 | K25: =IF(J25="", 0, IFERROR(XLOOKUP(J25, INDIRECT("'"&P25&"'!E4:E"), INDIRECT("'"&P25&"'!F4:F"), 0, 1), 0)) -> 202 | L25: 3.29 | M25: =IF(L25="", 0, IFERROR(XLOOKUP(L25, INDIRECT("'"&P25&"'!I4:I"), INDIRECT("'"&P25&"'!J4:J"), 0, -1), 0)) -> 302 | N25: 26 | O25: =IF(N25="", 0, IFERROR(XLOOKUP(N25, INDIRECT("'"&P25&"'!M4:M"), INDIRECT("'"&P25&"'!N4:N"), 0, -1), 0)) -> 209 | P25: =IF(OR(F25="6",F25="5"),IF(E25="W","Punkte W 5-6","Punkte M 5-6"),IF(E25="W","Punkte W 7-9","Punkte M 7-9")) -> Punkte M 5-6 | Q25: =IF(E25="W","Noten-Matrix-Mädchen","Noten-Matrix-Jungen") -> Noten-Matrix-Jungen | R25: =SUM(I25, K25, M25, O25) - MIN(I25, K25, M25, O25) -> 713 | S25: =IF(R25=0, "Keine Teilnahme", IFERROR(IF(R25>=VLOOKUP(G25&LOWER(E25), Formeln!$H$2:$K$30, 4, FALSE), "Ehrenurkunde", IF(R25>=VLOOKUP(G25&LOWER(E25), Formeln!$H$2:$K$30, 3, FALSE), "Siegerurkunde", "Teilnehmerurkunde")), "Keine Urkunde")) -> Teilnehmerurkunde | T25: =IF(R25=0, "Keine Teilnahme", IFERROR(XLOOKUP(R25, INDEX(INDIRECT("'"&Q25&"'!A:J"), 0, MATCH(G25, INDIRECT("'"&Q25&"'!A1:J1"), 0)), INDIRECT("'"&Q25&"'!A:A"), "Keine Note", -1), "Keine Note")) -> 3
A26: =IF(ASV_Daten!A2="","",ASV_Daten!A2) -> R5A | B26: =IF(ASV_Daten!B2="","",ASV_Daten!B2) -> Birkle | C26: =IF(ASV_Daten!C2="","",ASV_Daten!C2) -> Teresa | D26: =IF(ASV_Daten!D2="","",ASV_Daten!D2) -> 2015 | E26: W | F26: =MID(A26,2,1) -> 5 | G26: =2026-D26 -> 11 | I26: =IF(H26="", 0, IFERROR(XLOOKUP(H26, INDIRECT("'"&P26&"'!A4:A"), INDIRECT("'"&P26&"'!B4:B"), 0, 1), 0)) -> 0 | J26: 8.6 | K26: =IF(J26="", 0, IFERROR(XLOOKUP(J26, INDIRECT("'"&P26&"'!E4:E"), INDIRECT("'"&P26&"'!F4:F"), 0, 1), 0)) -> 304 | L26: 3.41 | M26: =IF(L26="", 0, IFERROR(XLOOKUP(L26, INDIRECT("'"&P26&"'!I4:I"), INDIRECT("'"&P26&"'!J4:J"), 0, -1), 0)) -> 362 | N26: 20 | O26: =IF(N26="", 0, IFERROR(XLOOKUP(N26, INDIRECT("'"&P26&"'!M4:M"), INDIRECT("'"&P26&"'!N4:N"), 0, -1), 0)) -> 280 | P26: =IF(OR(F26="6",F26="5"),IF(E26="W","Punkte W 5-6","Punkte M 5-6"),IF(E26="W","Punkte W 7-9","Punkte M 7-9")) -> Punkte W 5-6 | Q26: =IF(E26="W","Noten-Matrix-Mädchen","Noten-Matrix-Jungen") -> Noten-Matrix-Mädchen | R26: =SUM(I26, K26, M26, O26) - MIN(I26, K26, M26, O26) -> 946 | S26: =IF(R26=0, "Keine Teilnahme", IFERROR(IF(R26>=VLOOKUP(G26&LOWER(E26), Formeln!$H$2:$K$30, 4, FALSE), "Ehrenurkunde", IF(R26>=VLOOKUP(G26&LOWER(E26), Formeln!$H$2:$K$30, 3, FALSE), "Siegerurkunde", "Teilnehmerurkunde")), "Keine Urkunde")) -> Ehrenurkunde | T26: =IF(R26=0, "Keine Teilnahme", IFERROR(XLOOKUP(R26, INDEX(INDIRECT("'"&Q26&"'!A:J"), 0, MATCH(G26, INDIRECT("'"&Q26&"'!A1:J1"), 0)), INDIRECT("'"&Q26&"'!A:A"), "Keine Note", -1), "Keine Note")) -> 1.3
A27: =IF(ASV_Daten!A36="","",ASV_Daten!A36) -> R5B | B27: =IF(ASV_Daten!B36="","",ASV_Daten!B36) -> Kleiser | C27: =IF(ASV_Daten!C36="","",ASV_Daten!C36) -> Alicia | D27: =IF(ASV_Daten!D36="","",ASV_Daten!D36) -> 2015 | E27: =IF(ASV_Daten!E36="","",ASV_Daten!E36) -> W | F27: =MID(A27,2,1) -> 5 | G27: =2026-D27 -> 11 | I27: =IF(H27="", 0, IFERROR(XLOOKUP(H27, INDIRECT("'"&P27&"'!A4:A"), INDIRECT("'"&P27&"'!B4:B"), 0, 1), 0)) -> 0 | J27: 8.7 | K27: =IF(J27="", 0, IFERROR(XLOOKUP(J27, INDIRECT("'"&P27&"'!E4:E"), INDIRECT("'"&P27&"'!F4:F"), 0, 1), 0)) -> 294 | L27: 3.21 | M27: =IF(L27="", 0, IFERROR(XLOOKUP(L27, INDIRECT("'"&P27&"'!I4:I"), INDIRECT("'"&P27&"'!J4:J"), 0, -1), 0)) -> 335 | N27: 20 | O27: =IF(N27="", 0, IFERROR(XLOOKUP(N27, INDIRECT("'"&P27&"'!M4:M"), INDIRECT("'"&P27&"'!N4:N"), 0, -1), 0)) -> 280 | P27: =IF(OR(F27="6",F27="5"),IF(E27="W","Punkte W 5-6","Punkte M 5-6"),IF(E27="W","Punkte W 7-9","Punkte M 7-9")) -> Punkte W 5-6 | Q27: =IF(E27="W","Noten-Matrix-Mädchen","Noten-Matrix-Jungen") -> Noten-Matrix-Mädchen | R27: =SUM(I27, K27, M27, O27) - MIN(I27, K27, M27, O27) -> 909 | S27: =IF(R27=0, "Keine Teilnahme", IFERROR(IF(R27>=VLOOKUP(G27&LOWER(E27), Formeln!$H$2:$K$30, 4, FALSE), "Ehrenurkunde", IF(R27>=VLOOKUP(G27&LOWER(E27), Formeln!$H$2:$K$30, 3, FALSE), "Siegerurkunde", "Teilnehmerurkunde")), "Keine Urkunde")) -> Ehrenurkunde | T27: =IF(R27=0, "Keine Teilnahme", IFERROR(XLOOKUP(R27, INDEX(INDIRECT("'"&Q27&"'!A:J"), 0, MATCH(G27, INDIRECT("'"&Q27&"'!A1:J1"), 0)), INDIRECT("'"&Q27&"'!A:A"), "Keine Note", -1), "Keine Note")) -> 1.5
A28: =IF(ASV_Daten!A37="","",ASV_Daten!A37) -> R5B | B28: =IF(ASV_Daten!B37="","",ASV_Daten!B37) -> Lejosne | C28: =IF(ASV_Daten!C37="","",ASV_Daten!C37) -> Anastasiia | D28: =IF(ASV_Daten!D37="","",ASV_Daten!D37) -> 2015 | E28: =IF(ASV_Daten!E37="","",ASV_Daten!E37) -> W | F28: =MID(A28,2,1) -> 5 | G28: =2026-D28 -> 11 | I28: =IF(H28="", 0, IFERROR(XLOOKUP(H28, INDIRECT("'"&P28&"'!A4:A"), INDIRECT("'"&P28&"'!B4:B"), 0, 1), 0)) -> 0 | K28: =IF(J28="", 0, IFERROR(XLOOKUP(J28, INDIRECT("'"&P28&"'!E4:E"), INDIRECT("'"&P28&"'!F4:F"), 0, 1), 0)) -> 0 | M28: =IF(L28="", 0, IFERROR(XLOOKUP(L28, INDIRECT("'"&P28&"'!I4:I"), INDIRECT("'"&P28&"'!J4:J"), 0, -1), 0)) -> 0 | O28: =IF(N28="", 0, IFERROR(XLOOKUP(N28, INDIRECT("'"&P28&"'!M4:M"), INDIRECT("'"&P28&"'!N4:N"), 0, -1), 0)) -> 0 | P28: =IF(OR(F28="6",F28="5"),IF(E28="W","Punkte W 5-6","Punkte M 5-6"),IF(E28="W","Punkte W 7-9","Punkte M 7-9")) -> Punkte W 5-6 | Q28: =IF(E28="W","Noten-Matrix-Mädchen","Noten-Matrix-Jungen") -> Noten-Matrix-Mädchen | R28: =SUM(I28, K28, M28, O28) - MIN(I28, K28, M28, O28) -> 0 | S28: =IF(R28=0, "Keine Teilnahme", IFERROR(IF(R28>=VLOOKUP(G28&LOWER(E28), Formeln!$H$2:$K$30, 4, FALSE), "Ehrenurkunde", IF(R28>=VLOOKUP(G28&LOWER(E28), Formeln!$H$2:$K$30, 3, FALSE), "Siegerurkunde", "Teilnehmerurkunde")), "Keine Urkunde")) -> Keine Teilnahme | T28: =IF(R28=0, "Keine Teilnahme", IFERROR(XLOOKUP(R28, INDEX(INDIRECT("'"&Q28&"'!A:J"), 0, MATCH(G28, INDIRECT("'"&Q28&"'!A1:J1"), 0)), INDIRECT("'"&Q28&"'!A:A"), "Keine Note", -1), "Keine Note")) -> Keine Teilnahme
A29: =IF(ASV_Daten!A28="","",ASV_Daten!A28) -> R5B | B29: =IF(ASV_Daten!B28="","",ASV_Daten!B28) -> Buchova | C29: =IF(ASV_Daten!C28="","",ASV_Daten!C28) -> Anna | D29: =IF(ASV_Daten!D28="","",ASV_Daten!D28) -> 2015 | E29: =IF(ASV_Daten!E28="","",ASV_Daten!E28) -> W | F29: =MID(A29,2,1) -> 5 | G29: =2026-D29 -> 11 | I29: =IF(H29="", 0, IFERROR(XLOOKUP(H29, INDIRECT("'"&P29&"'!A4:A"), INDIRECT("'"&P29&"'!B4:B"), 0, 1), 0)) -> 0 | J29: 9.1 | K29: =IF(J29="", 0, IFERROR(XLOOKUP(J29, INDIRECT("'"&P29&"'!E4:E"), INDIRECT("'"&P29&"'!F4:F"), 0, 1), 0)) -> 258 | L29: 3.01 | M29: =IF(L29="", 0, IFERROR(XLOOKUP(L29, INDIRECT("'"&P29&"'!I4:I"), INDIRECT("'"&P29&"'!J4:J"), 0, -1), 0)) -> 308 | N29: 16.5 | O29: =IF(N29="", 0, IFERROR(XLOOKUP(N29, INDIRECT("'"&P29&"'!M4:M"), INDIRECT("'"&P29&"'!N4:N"), 0, -1), 0)) -> 233 | P29: =IF(OR(F29="6",F29="5"),IF(E29="W","Punkte W 5-6","Punkte M 5-6"),IF(E29="W","Punkte W 7-9","Punkte M 7-9")) -> Punkte W 5-6 | Q29: =IF(E29="W","Noten-Matrix-Mädchen","Noten-Matrix-Jungen") -> Noten-Matrix-Mädchen | R29: =SUM(I29, K29, M29, O29) - MIN(I29, K29, M29, O29) -> 799 | S29: =IF(R29=0, "Keine Teilnahme", IFERROR(IF(R29>=VLOOKUP(G29&LOWER(E29), Formeln!$H$2:$K$30, 4, FALSE), "Ehrenurkunde", IF(R29>=VLOOKUP(G29&LOWER(E29), Formeln!$H$2:$K$30, 3, FALSE), "Siegerurkunde", "Teilnehmerurkunde")), "Keine Urkunde")) -> Siegerurkunde | T29: =IF(R29=0, "Keine Teilnahme", IFERROR(XLOOKUP(R29, INDEX(INDIRECT("'"&Q29&"'!A:J"), 0, MATCH(G29, INDIRECT("'"&Q29&"'!A1:J1"), 0)), INDIRECT("'"&Q29&"'!A:A"), "Keine Note", -1), "Keine Note")) -> 2.1
A30: =IF(ASV_Daten!A42="","",ASV_Daten!A42) -> R5B | B30: =IF(ASV_Daten!B42="","",ASV_Daten!B42) -> Wider | C30: =IF(ASV_Daten!C42="","",ASV_Daten!C42) -> Anna-Maria | D30: =IF(ASV_Daten!D42="","",ASV_Daten!D42) -> 2015 | E30: =IF(ASV_Daten!E42="","",ASV_Daten!E42) -> W | F30: =MID(A30,2,1) -> 5 | G30: =2026-D30 -> 11 | H30: 0.12916667 | I30: =IF(H30="", 0, IFERROR(XLOOKUP(H30, INDIRECT("'"&P30&"'!A4:A"), INDIRECT("'"&P30&"'!B4:B"), 0, 1), 0)) -> 352 | K30: =IF(J30="", 0, IFERROR(XLOOKUP(J30, INDIRECT("'"&P30&"'!E4:E"), INDIRECT("'"&P30&"'!F4:F"), 0, 1), 0)) -> 0 | L30: 3.17 | M30: =IF(L30="", 0, IFERROR(XLOOKUP(L30, INDIRECT("'"&P30&"'!I4:I"), INDIRECT("'"&P30&"'!J4:J"), 0, -1), 0)) -> 330 | N30: 19 | O30: =IF(N30="", 0, IFERROR(XLOOKUP(N30, INDIRECT("'"&P30&"'!M4:M"), INDIRECT("'"&P30&"'!N4:N"), 0, -1), 0)) -> 267 | P30: =IF(OR(F30="6",F30="5"),IF(E30="W","Punkte W 5-6","Punkte M 5-6"),IF(E30="W","Punkte W 7-9","Punkte M 7-9")) -> Punkte W 5-6 | Q30: =IF(E30="W","Noten-Matrix-Mädchen","Noten-Matrix-Jungen") -> Noten-Matrix-Mädchen | R30: =SUM(I30, K30, M30, O30) - MIN(I30, K30, M30, O30) -> 949 | S30: =IF(R30=0, "Keine Teilnahme", IFERROR(IF(R30>=VLOOKUP(G30&LOWER(E30), Formeln!$H$2:$K$30, 4, FALSE), "Ehrenurkunde", IF(R30>=VLOOKUP(G30&LOWER(E30), Formeln!$H$2:$K$30, 3, FALSE), "Siegerurkunde", "Teilnehmerurkunde")), "Keine Urkunde")) -> Ehrenurkunde | T30: =IF(R30=0, "Keine Teilnahme", IFERROR(XLOOKUP(R30, INDEX(INDIRECT("'"&Q30&"'!A:J"), 0, MATCH(G30, INDIRECT("'"&Q30&"'!A1:J1"), 0)), INDIRECT("'"&Q30&"'!A:A"), "Keine Note", -1), "Keine Note")) -> 1.3
A31: =IF(ASV_Daten!A34="","",ASV_Daten!A34) -> R5B | B31: =IF(ASV_Daten!B34="","",ASV_Daten!B34) -> Jammali | C31: =IF(ASV_Daten!C34="","",ASV_Daten!C34) -> Elias | D31: =IF(ASV_Daten!D34="","",ASV_Daten!D34) -> 2014 | E31: =IF(ASV_Daten!E34="","",ASV_Daten!E34) -> W | F31: =MID(A31,2,1) -> 5 | G31: =2026-D31 -> 12 | H31: 4.38 | I31: =IF(H31="", 0, IFERROR(XLOOKUP(H31, INDIRECT("'"&P31&"'!A4:A"), INDIRECT("'"&P31&"'!B4:B"), 0, 1), 0)) -> Punkte | K31: =IF(J31="", 0, IFERROR(XLOOKUP(J31, INDIRECT("'"&P31&"'!E4:E"), INDIRECT("'"&P31&"'!F4:F"), 0, 1), 0)) -> 0 | L31: 2.45 | M31: =IF(L31="", 0, IFERROR(XLOOKUP(L31, INDIRECT("'"&P31&"'!I4:I"), INDIRECT("'"&P31&"'!J4:J"), 0, -1), 0)) -> 226 | N31: 20.5 | O31: =IF(N31="", 0, IFERROR(XLOOKUP(N31, INDIRECT("'"&P31&"'!M4:M"), INDIRECT("'"&P31&"'!N4:N"), 0, -1), 0)) -> 286 | P31: =IF(OR(F31="6",F31="5"),IF(E31="W","Punkte W 5-6","Punkte M 5-6"),IF(E31="W","Punkte W 7-9","Punkte M 7-9")) -> Punkte W 5-6 | Q31: =IF(E31="W","Noten-Matrix-Mädchen","Noten-Matrix-Jungen") -> Noten-Matrix-Mädchen | R31: =SUM(I31, K31, M31, O31) - MIN(I31, K31, M31, O31) -> 512 | S31: =IF(R31=0, "Keine Teilnahme", IFERROR(IF(R31>=VLOOKUP(G31&LOWER(E31), Formeln!$H$2:$K$30, 4, FALSE), "Ehrenurkunde", IF(R31>=VLOOKUP(G31&LOWER(E31), Formeln!$H$2:$K$30, 3, FALSE), "Siegerurkunde", "Teilnehmerurkunde")), "Keine Urkunde")) -> Teilnehmerurkunde | T31: =IF(R31=0, "Keine Teilnahme", IFERROR(XLOOKUP(R31, INDEX(INDIRECT("'"&Q31&"'!A:J"), 0, MATCH(G31, INDIRECT("'"&Q31&"'!A1:J1"), 0)), INDIRECT("'"&Q31&"'!A:A"), "Keine Note", -1), "Keine Note")) -> NOTE
A32: =IF(ASV_Daten!A38="","",ASV_Daten!A38) -> R5B | B32: =IF(ASV_Daten!B38="","",ASV_Daten!B38) -> Omodion | C32: =IF(ASV_Daten!C38="","",ASV_Daten!C38) -> Grace | D32: =IF(ASV_Daten!D38="","",ASV_Daten!D38) -> 2014 | E32: =IF(ASV_Daten!E38="","",ASV_Daten!E38) -> W | F32: =MID(A32,2,1) -> 5 | G32: =2026-D32 -> 12 | I32: =IF(H32="", 0, IFERROR(XLOOKUP(H32, INDIRECT("'"&P32&"'!A4:A"), INDIRECT("'"&P32&"'!B4:B"), 0, 1), 0)) -> 0 | J32: 7.8 | K32: =IF(J32="", 0, IFERROR(XLOOKUP(J32, INDIRECT("'"&P32&"'!E4:E"), INDIRECT("'"&P32&"'!F4:F"), 0, 1), 0)) -> 389 | L32: 3.65 | M32: =IF(L32="", 0, IFERROR(XLOOKUP(L32, INDIRECT("'"&P32&"'!I4:I"), INDIRECT("'"&P32&"'!J4:J"), 0, -1), 0)) -> 392 | N32: 17.5 | O32: =IF(N32="", 0, IFERROR(XLOOKUP(N32, INDIRECT("'"&P32&"'!M4:M"), INDIRECT("'"&P32&"'!N4:N"), 0, -1), 0)) -> 247 | P32: =IF(OR(F32="6",F32="5"),IF(E32="W","Punkte W 5-6","Punkte M 5-6"),IF(E32="W","Punkte W 7-9","Punkte M 7-9")) -> Punkte W 5-6 | Q32: =IF(E32="W","Noten-Matrix-Mädchen","Noten-Matrix-Jungen") -> Noten-Matrix-Mädchen | R32: =SUM(I32, K32, M32, O32) - MIN(I32, K32, M32, O32) -> 1028 | S32: =IF(R32=0, "Keine Teilnahme", IFERROR(IF(R32>=VLOOKUP(G32&LOWER(E32), Formeln!$H$2:$K$30, 4, FALSE), "Ehrenurkunde", IF(R32>=VLOOKUP(G32&LOWER(E32), Formeln!$H$2:$K$30, 3, FALSE), "Siegerurkunde", "Teilnehmerurkunde")), "Keine Urkunde")) -> Ehrenurkunde | T32: =IF(R32=0, "Keine Teilnahme", IFERROR(XLOOKUP(R32, INDEX(INDIRECT("'"&Q32&"'!A:J"), 0, MATCH(G32, INDIRECT("'"&Q32&"'!A1:J1"), 0)), INDIRECT("'"&Q32&"'!A:A"), "Keine Note", -1), "Keine Note")) -> 1.3
A33: =IF(ASV_Daten!A43="","",ASV_Daten!A43) -> R5B | B33: =IF(ASV_Daten!B43="","",ASV_Daten!B43) -> Zabel | C33: =IF(ASV_Daten!C43="","",ASV_Daten!C43) -> Hendrik | D33: =IF(ASV_Daten!D43="","",ASV_Daten!D43) -> 2015 | E33: =IF(ASV_Daten!E43="","",ASV_Daten!E43) -> M | F33: =MID(A33,2,1) -> 5 | G33: =2026-D33 -> 11 | H33: 0.21527778 | I33: =IF(H33="", 0, IFERROR(XLOOKUP(H33, INDIRECT("'"&P33&"'!A4:A"), INDIRECT("'"&P33&"'!B4:B"), 0, 1), 0)) -> 174 | K33: =IF(J33="", 0, IFERROR(XLOOKUP(J33, INDIRECT("'"&P33&"'!E4:E"), INDIRECT("'"&P33&"'!F4:F"), 0, 1), 0)) -> 0 | L33: 2.81 | M33: =IF(L33="", 0, IFERROR(XLOOKUP(L33, INDIRECT("'"&P33&"'!I4:I"), INDIRECT("'"&P33&"'!J4:J"), 0, -1), 0)) -> 240 | N33: 25 | O33: =IF(N33="", 0, IFERROR(XLOOKUP(N33, INDIRECT("'"&P33&"'!M4:M"), INDIRECT("'"&P33&"'!N4:N"), 0, -1), 0)) -> 200 | P33: =IF(OR(F33="6",F33="5"),IF(E33="W","Punkte W 5-6","Punkte M 5-6"),IF(E33="W","Punkte W 7-9","Punkte M 7-9")) -> Punkte M 5-6 | Q33: =IF(E33="W","Noten-Matrix-Mädchen","Noten-Matrix-Jungen") -> Noten-Matrix-Jungen | R33: =SUM(I33, K33, M33, O33) - MIN(I33, K33, M33, O33) -> 614 | S33: =IF(R33=0, "Keine Teilnahme", IFERROR(IF(R33>=VLOOKUP(G33&LOWER(E33), Formeln!$H$2:$K$30, 4, FALSE), "Ehrenurkunde", IF(R33>=VLOOKUP(G33&LOWER(E33), Formeln!$H$2:$K$30, 3, FALSE), "Siegerurkunde", "Teilnehmerurkunde")), "Keine Urkunde")) -> Teilnehmerurkunde | T33: =IF(R33=0, "Keine Teilnahme", IFERROR(XLOOKUP(R33, INDEX(INDIRECT("'"&Q33&"'!A:J"), 0, MATCH(G33, INDIRECT("'"&Q33&"'!A1:J1"), 0)), INDIRECT("'"&Q33&"'!A:A"), "Keine Note", -1), "Keine Note")) -> 3.2
A34: =IF(ASV_Daten!A32="","",ASV_Daten!A32) -> R5B | B34: =IF(ASV_Daten!B32="","",ASV_Daten!B32) -> Gross | C34: =IF(ASV_Daten!C32="","",ASV_Daten!C32) -> Lea | D34: =IF(ASV_Daten!D32="","",ASV_Daten!D32) -> 2015 | E34: =IF(ASV_Daten!E32="","",ASV_Daten!E32) -> W | F34: =MID(A34,2,1) -> 5 | G34: =2026-D34 -> 11 | H34: 0.14097222 | I34: =IF(H34="", 0, IFERROR(XLOOKUP(H34, INDIRECT("'"&P34&"'!A4:A"), INDIRECT("'"&P34&"'!B4:B"), 0, 1), 0)) -> 293 | K34: =IF(J34="", 0, IFERROR(XLOOKUP(J34, INDIRECT("'"&P34&"'!E4:E"), INDIRECT("'"&P34&"'!F4:F"), 0, 1), 0)) -> 0 | L34: 3.29 | M34: =IF(L34="", 0, IFERROR(XLOOKUP(L34, INDIRECT("'"&P34&"'!I4:I"), INDIRECT("'"&P34&"'!J4:J"), 0, -1), 0)) -> 346 | N34: 20.5 | O34: =IF(N34="", 0, IFERROR(XLOOKUP(N34, INDIRECT("'"&P34&"'!M4:M"), INDIRECT("'"&P34&"'!N4:N"), 0, -1), 0)) -> 286 | P34: =IF(OR(F34="6",F34="5"),IF(E34="W","Punkte W 5-6","Punkte M 5-6"),IF(E34="W","Punkte W 7-9","Punkte M 7-9")) -> Punkte W 5-6 | Q34: =IF(E34="W","Noten-Matrix-Mädchen","Noten-Matrix-Jungen") -> Noten-Matrix-Mädchen | R34: =SUM(I34, K34, M34, O34) - MIN(I34, K34, M34, O34) -> 925 | S34: =IF(R34=0, "Keine Teilnahme", IFERROR(IF(R34>=VLOOKUP(G34&LOWER(E34), Formeln!$H$2:$K$30, 4, FALSE), "Ehrenurkunde", IF(R34>=VLOOKUP(G34&LOWER(E34), Formeln!$H$2:$K$30, 3, FALSE), "Siegerurkunde", "Teilnehmerurkunde")), "Keine Urkunde")) -> Ehrenurkunde | T34: =IF(R34=0, "Keine Teilnahme", IFERROR(XLOOKUP(R34, INDEX(INDIRECT("'"&Q34&"'!A:J"), 0, MATCH(G34, INDIRECT("'"&Q34&"'!A1:J1"), 0)), INDIRECT("'"&Q34&"'!A:A"), "Keine Note", -1), "Keine Note")) -> 1.4
A35: =IF(ASV_Daten!A29="","",ASV_Daten!A29) -> R5B | B35: =IF(ASV_Daten!B29="","",ASV_Daten!B29) -> Eidinger | C35: =IF(ASV_Daten!C29="","",ASV_Daten!C29) -> Leif | D35: =IF(ASV_Daten!D29="","",ASV_Daten!D29) -> 2014 | E35: =IF(ASV_Daten!E29="","",ASV_Daten!E29) -> M | F35: =MID(A35,2,1) -> 5 | G35: =2026-D35 -> 12 | I35: =IF(H35="", 0, IFERROR(XLOOKUP(H35, INDIRECT("'"&P35&"'!A4:A"), INDIRECT("'"&P35&"'!B4:B"), 0, 1), 0)) -> 0 | J35: 9.1 | K35: =IF(J35="", 0, IFERROR(XLOOKUP(J35, INDIRECT("'"&P35&"'!E4:E"), INDIRECT("'"&P35&"'!F4:F"), 0, 1), 0)) -> 226 | L35: 2.93 | M35: =IF(L35="", 0, IFERROR(XLOOKUP(L35, INDIRECT("'"&P35&"'!I4:I"), INDIRECT("'"&P35&"'!J4:J"), 0, -1), 0)) -> 256 | N35: 21 | O35: =IF(N35="", 0, IFERROR(XLOOKUP(N35, INDIRECT("'"&P35&"'!M4:M"), INDIRECT("'"&P35&"'!N4:N"), 0, -1), 0)) -> 162 | P35: =IF(OR(F35="6",F35="5"),IF(E35="W","Punkte W 5-6","Punkte M 5-6"),IF(E35="W","Punkte W 7-9","Punkte M 7-9")) -> Punkte M 5-6 | Q35: =IF(E35="W","Noten-Matrix-Mädchen","Noten-Matrix-Jungen") -> Noten-Matrix-Jungen | R35: =SUM(I35, K35, M35, O35) - MIN(I35, K35, M35, O35) -> 644 | S35: =IF(R35=0, "Keine Teilnahme", IFERROR(IF(R35>=VLOOKUP(G35&LOWER(E35), Formeln!$H$2:$K$30, 4, FALSE), "Ehrenurkunde", IF(R35>=VLOOKUP(G35&LOWER(E35), Formeln!$H$2:$K$30, 3, FALSE), "Siegerurkunde", "Teilnehmerurkunde")), "Keine Urkunde")) -> Teilnehmerurkunde | T35: =IF(R35=0, "Keine Teilnahme", IFERROR(XLOOKUP(R35, INDEX(INDIRECT("'"&Q35&"'!A:J"), 0, MATCH(G35, INDIRECT("'"&Q35&"'!A1:J1"), 0)), INDIRECT("'"&Q35&"'!A:A"), "Keine Note", -1), "Keine Note")) -> 3.5
A36: =IF(ASV_Daten!A35="","",ASV_Daten!A35) -> R5B | B36: =IF(ASV_Daten!B35="","",ASV_Daten!B35) -> Jordan | C36: =IF(ASV_Daten!C35="","",ASV_Daten!C35) -> Lena | D36: =IF(ASV_Daten!D35="","",ASV_Daten!D35) -> 2014 | E36: =IF(ASV_Daten!E35="","",ASV_Daten!E35) -> W | F36: =MID(A36,2,1) -> 5 | G36: =2026-D36 -> 12 | H36: 0.18194444 | I36: =IF(H36="", 0, IFERROR(XLOOKUP(H36, INDIRECT("'"&P36&"'!A4:A"), INDIRECT("'"&P36&"'!B4:B"), 0, 1), 0)) -> 155 | K36: =IF(J36="", 0, IFERROR(XLOOKUP(J36, INDIRECT("'"&P36&"'!E4:E"), INDIRECT("'"&P36&"'!F4:F"), 0, 1), 0)) -> 0 | L36: 2.37 | M36: =IF(L36="", 0, IFERROR(XLOOKUP(L36, INDIRECT("'"&P36&"'!I4:I"), INDIRECT("'"&P36&"'!J4:J"), 0, -1), 0)) -> 214 | N36: 9 | O36: =IF(N36="", 0, IFERROR(XLOOKUP(N36, INDIRECT("'"&P36&"'!M4:M"), INDIRECT("'"&P36&"'!N4:N"), 0, -1), 0)) -> 111 | P36: =IF(OR(F36="6",F36="5"),IF(E36="W","Punkte W 5-6","Punkte M 5-6"),IF(E36="W","Punkte W 7-9","Punkte M 7-9")) -> Punkte W 5-6 | Q36: =IF(E36="W","Noten-Matrix-Mädchen","Noten-Matrix-Jungen") -> Noten-Matrix-Mädchen | R36: =SUM(I36, K36, M36, O36) - MIN(I36, K36, M36, O36) -> 480 | S36: =IF(R36=0, "Keine Teilnahme", IFERROR(IF(R36>=VLOOKUP(G36&LOWER(E36), Formeln!$H$2:$K$30, 4, FALSE), "Ehrenurkunde", IF(R36>=VLOOKUP(G36&LOWER(E36), Formeln!$H$2:$K$30, 3, FALSE), "Siegerurkunde", "Teilnehmerurkunde")), "Keine Urkunde")) -> Teilnehmerurkunde | T36: =IF(R36=0, "Keine Teilnahme", IFERROR(XLOOKUP(R36, INDEX(INDIRECT("'"&Q36&"'!A:J"), 0, MATCH(G36, INDIRECT("'"&Q36&"'!A1:J1"), 0)), INDIRECT("'"&Q36&"'!A:A"), "Keine Note", -1), "Keine Note")) -> NOTE
A37: =IF(ASV_Daten!A31="","",ASV_Daten!A31) -> R5B | B37: =IF(ASV_Daten!B31="","",ASV_Daten!B31) -> Frisch | C37: =IF(ASV_Daten!C31="","",ASV_Daten!C31) -> Mattis | D37: =IF(ASV_Daten!D31="","",ASV_Daten!D31) -> 2014 | E37: =IF(ASV_Daten!E31="","",ASV_Daten!E31) -> M | F37: =MID(A37,2,1) -> 5 | G37: =2026-D37 -> 12 | I37: =IF(H37="", 0, IFERROR(XLOOKUP(H37, INDIRECT("'"&P37&"'!A4:A"), INDIRECT("'"&P37&"'!B4:B"), 0, 1), 0)) -> 0 | J37: 8.6 | K37: =IF(J37="", 0, IFERROR(XLOOKUP(J37, INDIRECT("'"&P37&"'!E4:E"), INDIRECT("'"&P37&"'!F4:F"), 0, 1), 0)) -> 270 | L37: 3.33 | M37: =IF(L37="", 0, IFERROR(XLOOKUP(L37, INDIRECT("'"&P37&"'!I4:I"), INDIRECT("'"&P37&"'!J4:J"), 0, -1), 0)) -> 308 | N37: 27 | O37: =IF(N37="", 0, IFERROR(XLOOKUP(N37, INDIRECT("'"&P37&"'!M4:M"), INDIRECT("'"&P37&"'!N4:N"), 0, -1), 0)) -> 217 | P37: =IF(OR(F37="6",F37="5"),IF(E37="W","Punkte W 5-6","Punkte M 5-6"),IF(E37="W","Punkte W 7-9","Punkte M 7-9")) -> Punkte M 5-6 | Q37: =IF(E37="W","Noten-Matrix-Mädchen","Noten-Matrix-Jungen") -> Noten-Matrix-Jungen | R37: =SUM(I37, K37, M37, O37) - MIN(I37, K37, M37, O37) -> 795 | S37: =IF(R37=0, "Keine Teilnahme", IFERROR(IF(R37>=VLOOKUP(G37&LOWER(E37), Formeln!$H$2:$K$30, 4, FALSE), "Ehrenurkunde", IF(R37>=VLOOKUP(G37&LOWER(E37), Formeln!$H$2:$K$30, 3, FALSE), "Siegerurkunde", "Teilnehmerurkunde")), "Keine Urkunde")) -> Siegerurkunde | T37: =IF(R37=0, "Keine Teilnahme", IFERROR(XLOOKUP(R37, INDEX(INDIRECT("'"&Q37&"'!A:J"), 0, MATCH(G37, INDIRECT("'"&Q37&"'!A1:J1"), 0)), INDIRECT("'"&Q37&"'!A:A"), "Keine Note", -1), "Keine Note")) -> 2.5
A38: =IF(ASV_Daten!A27="","",ASV_Daten!A27) -> R5B | B38: =IF(ASV_Daten!B27="","",ASV_Daten!B27) -> Babanin | C38: =IF(ASV_Daten!C27="","",ASV_Daten!C27) -> Michelle | D38: =IF(ASV_Daten!D27="","",ASV_Daten!D27) -> 2015 | E38: =IF(ASV_Daten!E27="","",ASV_Daten!E27) -> W | F38: =MID(A38,2,1) -> 5 | G38: =2026-D38 -> 11 | I38: =IF(H38="", 0, IFERROR(XLOOKUP(H38, INDIRECT("'"&P38&"'!A4:A"), INDIRECT("'"&P38&"'!B4:B"), 0, 1), 0)) -> 0 | J38: 7.7 | K38: =IF(J38="", 0, IFERROR(XLOOKUP(J38, INDIRECT("'"&P38&"'!E4:E"), INDIRECT("'"&P38&"'!F4:F"), 0, 1), 0)) -> 401 | L38: 3.53 | M38: =IF(L38="", 0, IFERROR(XLOOKUP(L38, INDIRECT("'"&P38&"'!I4:I"), INDIRECT("'"&P38&"'!J4:J"), 0, -1), 0)) -> 377 | N38: 27 | O38: =IF(N38="", 0, IFERROR(XLOOKUP(N38, INDIRECT("'"&P38&"'!M4:M"), INDIRECT("'"&P38&"'!N4:N"), 0, -1), 0)) -> 363 | P38: =IF(OR(F38="6",F38="5"),IF(E38="W","Punkte W 5-6","Punkte M 5-6"),IF(E38="W","Punkte W 7-9","Punkte M 7-9")) -> Punkte W 5-6 | Q38: =IF(E38="W","Noten-Matrix-Mädchen","Noten-Matrix-Jungen") -> Noten-Matrix-Mädchen | R38: =SUM(I38, K38, M38, O38) - MIN(I38, K38, M38, O38) -> 1141 | S38: =IF(R38=0, "Keine Teilnahme", IFERROR(IF(R38>=VLOOKUP(G38&LOWER(E38), Formeln!$H$2:$K$30, 4, FALSE), "Ehrenurkunde", IF(R38>=VLOOKUP(G38&LOWER(E38), Formeln!$H$2:$K$30, 3, FALSE), "Siegerurkunde", "Teilnehmerurkunde")), "Keine Urkunde")) -> Ehrenurkunde | T38: =IF(R38=0, "Keine Teilnahme", IFERROR(XLOOKUP(R38, INDEX(INDIRECT("'"&Q38&"'!A:J"), 0, MATCH(G38, INDIRECT("'"&Q38&"'!A1:J1"), 0)), INDIRECT("'"&Q38&"'!A:A"), "Keine Note", -1), "Keine Note")) -> 1
A39: =IF(ASV_Daten!A40="","",ASV_Daten!A40) -> R5B | B39: =IF(ASV_Daten!B40="","",ASV_Daten!B40) -> Saum | C39: =IF(ASV_Daten!C40="","",ASV_Daten!C40) -> Noela | D39: =IF(ASV_Daten!D40="","",ASV_Daten!D40) -> 2015 | E39: =IF(ASV_Daten!E40="","",ASV_Daten!E40) -> W | F39: =MID(A39,2,1) -> 5 | G39: =2026-D39 -> 11 | I39: =IF(H39="", 0, IFERROR(XLOOKUP(H39, INDIRECT("'"&P39&"'!A4:A"), INDIRECT("'"&P39&"'!B4:B"), 0, 1), 0)) -> 0 | J39: 9.6 | K39: =IF(J39="", 0, IFERROR(XLOOKUP(J39, INDIRECT("'"&P39&"'!E4:E"), INDIRECT("'"&P39&"'!F4:F"), 0, 1), 0)) -> 217 | L39: 2.81 | M39: =IF(L39="", 0, IFERROR(XLOOKUP(L39, INDIRECT("'"&P39&"'!I4:I"), INDIRECT("'"&P39&"'!J4:J"), 0, -1), 0)) -> 280 | N39: 16 | O39: =IF(N39="", 0, IFERROR(XLOOKUP(N39, INDIRECT("'"&P39&"'!M4:M"), INDIRECT("'"&P39&"'!N4:N"), 0, -1), 0)) -> 226 | P39: =IF(OR(F39="6",F39="5"),IF(E39="W","Punkte W 5-6","Punkte M 5-6"),IF(E39="W","Punkte W 7-9","Punkte M 7-9")) -> Punkte W 5-6 | Q39: =IF(E39="W","Noten-Matrix-Mädchen","Noten-Matrix-Jungen") -> Noten-Matrix-Mädchen | R39: =SUM(I39, K39, M39, O39) - MIN(I39, K39, M39, O39) -> 723 | S39: =IF(R39=0, "Keine Teilnahme", IFERROR(IF(R39>=VLOOKUP(G39&LOWER(E39), Formeln!$H$2:$K$30, 4, FALSE), "Ehrenurkunde", IF(R39>=VLOOKUP(G39&LOWER(E39), Formeln!$H$2:$K$30, 3, FALSE), "Siegerurkunde", "Teilnehmerurkunde")), "Keine Urkunde")) -> Siegerurkunde | T39: =IF(R39=0, "Keine Teilnahme", IFERROR(XLOOKUP(R39, INDEX(INDIRECT("'"&Q39&"'!A:J"), 0, MATCH(G39, INDIRECT("'"&Q39&"'!A1:J1"), 0)), INDIRECT("'"&Q39&"'!A:A"), "Keine Note", -1), "Keine Note")) -> 2.6
